Workbook

Sheet Summary
A1: demo-mine / Summary
A4: SYNTHETIC EXAMPLE
A7: Active scenario | B7: =Assumptions!B4 -> base
A8: Model value per share | B8: =Valuation!$B$11 -> 3.6305785
A9: Equity value | B9: =Valuation!$B$9 -> 363.05785
A10: Minimum illustrative cash | B10: =Valuation!$B$12 -> 100
A12: Markdown is the main research narrative. Use this workbook to inspect and edit detailed assumptions; recalculate in Excel or LibreOffice, save, then import to publish a validated snapshot back to the research memo.
A16: Known limitations: See Readme for the full limitations register.

Sheet Assumptions
A1: demo-mine / Assumptions
A4: Active scenario | B4: base | C4: Blue = editable inputs • Green = cross-sheet links • Black = calculations
A7: Cash | B7: 100 | C7: AUD
A8: Debt | B8: 20 | C8: AUD
A9: Other Assets | B9: 0 | C9: AUD
A10: Diluted Shares | B10: 100 | C10: shares
A11: Reference Price | B11: 2 | C11: AUD/share
A12: Valuation Date | B12: 2026-09-20 | C12: YYYY-MM-DD
A13: Quote Date | B13: 2026-09-18 | C13: YYYY-MM-DD
A15: Enter dates as YYYY-MM-DD text. Blank quote and reference price mean no market comparison. Preserve the declared ownership basis; attributable inputs require ownership = 100%.
A19: BEAR / whole_operation
A20: Discount Rate | B20: 0.1
A21: Ownership | B21: 0.5
A22: Residual Value | B22: 0
A23: Explicit forecast periods | B23: 2
C24: 2027 | D24: 2028
A25: Payable Tonnes | B25: tonnes | C25: 10 | D25: 10
A26: Price | B26: USD/tonne | C26: 80 | D26: 80
A27: Fx | B27: AUD/USD | C27: 1 | D27: 1
A28: Unit Cost | B28: AUD/tonne | C28: 40 | D28: 40
A29: Royalty Rate | B29: fraction | C29: 0 | D29: 0
A30: Tax Rate | B30: fraction | C30: 0.25 | D30: 0.25
A31: Depreciation | B31: AUD | C31: 0 | D31: 0
A32: Capex | B32: AUD | C32: 100 | D32: 100
A33: Working Capital Change | B33: AUD | C33: 0 | D33: 0
A34: Closure | B34: AUD | C34: 0 | D34: 50
A35: Corporate Cost | B35: AUD | C35: 0 | D35: 0
A38: BASE / whole_operation
A39: Discount Rate | B39: 0.1
A40: Ownership | B40: 0.5
A41: Residual Value | B41: 0
A42: Explicit forecast periods | B42: 2
C43: 2027 | D43: 2028
A44: Payable Tonnes | B44: tonnes | C44: 10 | D44: 10
A45: Price | B45: USD/tonne | C45: 100 | D45: 100
A46: Fx | B46: AUD/USD | C46: 1 | D46: 1
A47: Unit Cost | B47: AUD/tonne | C47: 40 | D47: 40
A48: Royalty Rate | B48: fraction | C48: 0 | D48: 0
A49: Tax Rate | B49: fraction | C49: 0.25 | D49: 0.25
A50: Depreciation | B50: AUD | C50: 0 | D50: 0
...

Sheet Historical
A1: demo-mine / Historical
A4: Source-linked reported facts. Historical coverage may be incomplete; no integrated statements are inferred.
A6: Metric | B6: Period | C6: Value | D6: Unit | E6: Currency | F6: Basis / ownership | G6: Published | H6: Source | I6: Page

Sheet Operating
A1: demo-mine / Operating
A4: Discount Rate | B4: =IF(Assumptions!$B$4="bear",Assumptions!$B$20,IF(Assumptions!$B$4="base",Assumptions!$B$39,Assumptions!$B$58)) -> 0.1
A5: Ownership | B5: =IF(Assumptions!$B$4="bear",Assumptions!$B$21,IF(Assumptions!$B$4="base",Assumptions!$B$40,Assumptions!$B$59)) -> 0.5
A6: Residual Value | B6: =IF(Assumptions!$B$4="bear",Assumptions!$B$22,IF(Assumptions!$B$4="base",Assumptions!$B$41,Assumptions!$B$60)) -> 0
A7: Horizon | B7: =IF(Assumptions!$B$4="bear",Assumptions!$B$23,IF(Assumptions!$B$4="base",Assumptions!$B$42,Assumptions!$B$61)) -> 2
A8: Volume basis | B8: =IF(Assumptions!$B$4="bear","payable_sales",IF(Assumptions!$B$4="base","payable_sales","payable_sales")) -> payable_sales
A9: Annual end-of-period forecast | C9: =YEAR(DATEVALUE(Assumptions!$B$12))+1 -> 2027 | D9: =YEAR(DATEVALUE(Assumptions!$B$12))+2 -> 2028
A10: Volume (see case basis) | B10: tonnes | C10: =IF(Assumptions!$B$4="bear",Assumptions!$C$25,IF(Assumptions!$B$4="base",Assumptions!$C$44,Assumptions!$C$63)) -> 10 | D10: =IF(Assumptions!$B$4="bear",Assumptions!$D$25,IF(Assumptions!$B$4="base",Assumptions!$D$44,Assumptions!$D$63)) -> 10
A11: Price | B11: see case input units | C11: =IF(Assumptions!$B$4="bear",Assumptions!$C$26,IF(Assumptions!$B$4="base",Assumptions!$C$45,Assumptions!$C$64)) -> 100 | D11: =IF(Assumptions!$B$4="bear",Assumptions!$D$26,IF(Assumptions!$B$4="base",Assumptions!$D$45,Assumptions!$D$64)) -> 100
A12: Fx | B12: see case input units | C12: =IF(Assumptions!$B$4="bear",Assumptions!$C$27,IF(Assumptions!$B$4="base",Assumptions!$C$46,Assumptions!$C$65)) -> 1 | D12: =IF(Assumptions!$B$4="bear",Assumptions!$D$27,IF(Assumptions!$B$4="base",Assumptions!$D$46,Assumptions!$D$65)) -> 1
A13: Unit Cost | B13: AUD/tonne | C13: =IF(Assumptions!$B$4="bear",Assumptions!$C$28,IF(Assumptions!$B$4="base",Assumptions!$C$47,Assumptions!$C$66)) -> 40 | D13: =IF(Assumptions!$B$4="bear",Assumptions!$D$28,IF(Assumptions!$B$4="base",Assumptions!$D$47,Assumptions!$D$66)) -> 40
A14: Royalty Rate | B14: fraction | C14: =IF(Assumptions!$B$4="bear",Assumptions!$C$29,IF(Assumptions!$B$4="base",Assumptions!$C$48,Assumptions!$C$67)) -> 0 | D14: =IF(Assumptions!$B$4="bear",Assumptions!$D$29,IF(Assumptions!$B$4="base",Assumptions!$D$48,Assumptions!$D$67)) -> 0
A15: Tax Rate | B15: fraction | C15: =IF(Assumptions!$B$4="bear",Assumptions!$C$30,IF(Assumptions!$B$4="base",Assumptions!$C$49,Assumptions!$C$68)) -> 0.25 | D15: =IF(Assumptions!$B$4="bear",Assumptions!$D$30,IF(Assumptions!$B$4="base",Assumptions!$D$49,Assumptions!$D$68)) -> 0.25
A16: Depreciation | B16: AUD | C16: =IF(Assumptions!$B$4="bear",Assumptions!$C$31,IF(Assumptions!$B$4="base",Assumptions!$C$50,Assumptions!$C$69)) -> 0 | D16: =IF(Assumptions!$B$4="bear",Assumptions!$D$31,IF(Assumptions!$B$4="base",Assumptions!$D$50,Assumptions!$D$69)) -> 0
A17: Capex | B17: AUD | C17: =IF(Assumptions!$B$4="bear",Assumptions!$C$32,IF(Assumptions!$B$4="base",Assumptions!$C$51,Assumptions!$C$70)) -> 100 | D17: =IF(Assumptions!$B$4="bear",Assumptions!$D$32,IF(Assumptions!$B$4="base",Assumptions!$D$51,Assumptions!$D$70)) -> 100
A18: Working Capital Change | B18: AUD | C18: =IF(Assumptions!$B$4="bear",Assumptions!$C$33,IF(Assumptions!$B$4="base",Assumptions!$C$52,Assumptions!$C$71)) -> 0 | D18: =IF(Assumptions!$B$4="bear",Assumptions!$D$33,IF(Assumptions!$B$4="base",Assumptions!$D$52,Assumptions!$D$71)) -> 0
A19: Closure | B19: AUD | C19: =IF(Assumptions!$B$4="bear",Assumptions!$C$34,IF(Assumptions!$B$4="base",Assumptions!$C$53,Assumptions!$C$72)) -> 0 | D19: =IF(Assumptions!$B$4="bear",Assumptions!$D$34,IF(Assumptions!$B$4="base",Assumptions!$D$53,Assumptions!$D$72)) -> 50
A20: Corporate Cost | B20: AUD | C20: =IF(Assumptions!$B$4="bear",Assumptions!$C$35,IF(Assumptions!$B$4="base",Assumptions!$C$54,Assumptions!$C$73)) -> 0 | D20: =IF(Assumptions!$B$4="bear",Assumptions!$D$35,IF(Assumptions!$B$4="base",Assumptions!$D$54,Assumptions!$D$73)) -> 0
A23: Revenue | B23: AUD | C23: =Operating!$C$10*Operating!$C$11*Operating!$C$12 -> 1000 | D23: =Operating!$D$10*Operating!$D$11*Operating!$D$12 -> 1000
A24: Operating Cost | B24: AUD | C24: =Operating!$C$10*Operating!$C$13 -> 400 | D24: =Operating!$D$10*Operating!$D$13 -> 400
A25: Royalties | B25: AUD | C25: =Operating!$C$23*Operating!$C$14 -> 0 | D25: =Operating!$D$23*Operating!$D$14 -> 0
A26: Ebit | B26: AUD | C26: =Operating!$C$23-Operating!$C$24-Operating!$C$25-Operating!$C$16 -> 600 | D26: =Operating!$D$23-Operating!$D$24-Operating!$D$25-Operating!$D$16 -> 600
A27: Tax | B27: AUD | C27: =MAX(0,Operating!$C$26)*Operating!$C$15 -> 150 | D27: =MAX(0,Operating!$D$26)*Operating!$D$15 -> 150
A28: Nopat | B28: AUD | C28: =Operating!$C$26-Operating!$C$27 -> 450 | D28: =Operating!$D$26-Operating!$D$27 -> 450
A29: Operating Fcf | B29: AUD | C29: =Operating!$C$28+Operating!$C$16-Operating!$C$17-Operating!$C$18-Operating!$C$19 -> 350 | D29: =Operating!$D$28+Operating!$D$16-Operating!$D$17-Operating!$D$18-Operating!$D$19 -> 300
A30: Fcf | B30: AUD | C30: =Operating!$C$29*Operating!$B$5-Operating!$C$20+IF(1=Operating!$B$7,Operating!$B$6,0) -> 175 | D30: =Operating!$D$29*Operating!$B$5-Operating!$D$20+IF(2=Operating!$B$7,Operating!$B$6,0) -> 150
A31: Present Value | B31: AUD | C31: =Operating!$C$30/(1+Operating!$B$4)^1 -> 159.09091 | D31: =Operating!$D$30/(1+Operating!$B$4)^2 -> 123.96694
A32: Illustrative Cash | B32: AUD | C32: =Assumptions!$B$7+Operating!$C$30 -> 275 | D32: =Operating!$C$32+Operating!$D$30 -> 425
A34: Illustrative cash excludes financing, dividends and debt maturities. This is a finite cash-flow schedule, not an integrated three-statement forecast. No terminal perpetuity is assumed.

Sheet Valuation
A1: demo-mine / Valuation
A5: Enterprise Value | B5: =SUM(Operating!C31:D31) -> 283.05785 | C5: AUD
A6: Cash | B6: =Assumptions!$B$7 -> 100 | C6: AUD
A7: Other Assets | B7: =Assumptions!$B$9 -> 0 | C7: AUD
A8: Debt | B8: =Assumptions!$B$8 -> 20 | C8: AUD
A9: Equity Value | B9: =B5+B6+B7-B8 -> 363.05785 | C9: AUD
A10: Diluted Shares | B10: =Assumptions!$B$10 -> 100 | C10: shares
A11: Per Share | B11: =B9/B10 -> 3.6305785 | C11: AUD/share
A12: Minimum Illustrative Cash | B12: =MIN(Assumptions!$B$7,Operating!C32:D32) -> 100 | C12: AUD
A15: Reference price | B15: =IF(Assumptions!$B$11="","Unavailable",Assumptions!$B$11) -> 2
A16: Model / reference price − 1 | B16: =IF(AND(ISNUMBER(B15),B15>0),B11/B15-1,"Unavailable") -> 0.81528926
A19: This is a model output, not a price target or investment recommendation. Corporate costs and residual value are company-attributable; operating cash flows apply ownership once. Residual value is explicit, not a perpetuity.

Sheet Sensitivities
A1: demo-mine / Sensitivities
A4: Price multiplier × discount rate / AUD per share. All active-case forecast years recomputed, including positive-EBIT tax floor.
C7: =MAX(0,Operating!$B$4+(-0.02)) -> 0.08 | D7: =MAX(0,Operating!$B$4+(0)) -> 0.1 | E7: =MAX(0,Operating!$B$4+(0.02)) -> 0.12
B8: 0.8 | C8: =(SUM(C17:D17)+Assumptions!$B$7+Assumptions!$B$9-Assumptions!$B$8)/Assumptions!$B$10 -> 2.36893 | D8: =(SUM(C18:D18)+Assumptions!$B$7+Assumptions!$B$9-Assumptions!$B$8)/Assumptions!$B$10 -> 2.3289256 | E8: =(SUM(C19:D19)+Assumptions!$B$7+Assumptions!$B$9-Assumptions!$B$8)/Assumptions!$B$10 -> 2.2907526
B9: 1 | C9: =(SUM(C20:D20)+Assumptions!$B$7+Assumptions!$B$9-Assumptions!$B$8)/Assumptions!$B$10 -> 3.7063786 | D9: =(SUM(C21:D21)+Assumptions!$B$7+Assumptions!$B$9-Assumptions!$B$8)/Assumptions!$B$10 -> 3.6305785 | E9: =(SUM(C22:D22)+Assumptions!$B$7+Assumptions!$B$9-Assumptions!$B$8)/Assumptions!$B$10 -> 3.5582908
B10: 1.2 | C10: =(SUM(C23:D23)+Assumptions!$B$7+Assumptions!$B$9-Assumptions!$B$8)/Assumptions!$B$10 -> 5.0438272 | D10: =(SUM(C24:D24)+Assumptions!$B$7+Assumptions!$B$9-Assumptions!$B$8)/Assumptions!$B$10 -> 4.9322314 | E10: =(SUM(C25:D25)+Assumptions!$B$7+Assumptions!$B$9-Assumptions!$B$8)/Assumptions!$B$10 -> 4.8258291
A15: Auditable discounted-cash-flow helpers
A17: Driver 0.8× / rate column 1 | C17: =(((((Operating!$C$10*Operating!$C$11*Operating!$C$12*$B$8)*(1-Operating!$C$14)-Operating!$C$10*Operating!$C$13-Operating!$C$16)-MAX(0,((Operating!$C$10*Operating!$C$11*Operating!$C$12*$B$8)*(1-Operating!$C$14)-Operating!$C$10*Operating!$C$13-Operating!$C$16))*Operating!$C$15)+Operating!$C$16-Operating!$C$17-Operating!$C$18-Operating!$C$19)*Operating!$B$5-Operating!$C$20+IF(1=Operating!$B$7,Operating!$B$6,0))/(1+C7)^1 -> 92.592593 | D17: =(((((Operating!$D$10*Operating!$D$11*Operating!$D$12*$B$8)*(1-Operating!$D$14)-Operating!$D$10*Operating!$D$13-Operating!$D$16)-MAX(0,((Operating!$D$10*Operating!$D$11*Operating!$D$12*$B$8)*(1-Operating!$D$14)-Operating!$D$10*Operating!$D$13-Operating!$D$16))*Operating!$D$15)+Operating!$D$16-Operating!$D$17-Operating!$D$18-Operating!$D$19)*Operating!$B$5-Operating!$D$20+IF(2=Operating!$B$7,Operating!$B$6,0))/(1+C7)^2 -> 64.300412
A18: Driver 0.8× / rate column 2 | C18: =(((((Operating!$C$10*Operating!$C$11*Operating!$C$12*$B$8)*(1-Operating!$C$14)-Operating!$C$10*Operating!$C$13-Operating!$C$16)-MAX(0,((Operating!$C$10*Operating!$C$11*Operating!$C$12*$B$8)*(1-Operating!$C$14)-Operating!$C$10*Operating!$C$13-Operating!$C$16))*Operating!$C$15)+Operating!$C$16-Operating!$C$17-Operating!$C$18-Operating!$C$19)*Operating!$B$5-Operating!$C$20+IF(1=Operating!$B$7,Operating!$B$6,0))/(1+D7)^1 -> 90.909091 | D18: =(((((Operating!$D$10*Operating!$D$11*Operating!$D$12*$B$8)*(1-Operating!$D$14)-Operating!$D$10*Operating!$D$13-Operating!$D$16)-MAX(0,((Operating!$D$10*Operating!$D$11*Operating!$D$12*$B$8)*(1-Operating!$D$14)-Operating!$D$10*Operating!$D$13-Operating!$D$16))*Operating!$D$15)+Operating!$D$16-Operating!$D$17-Operating!$D$18-Operating!$D$19)*Operating!$B$5-Operating!$D$20+IF(2=Operating!$B$7,Operating!$B$6,0))/(1+D7)^2 -> 61.983471
A19: Driver 0.8× / rate column 3 | C19: =(((((Operating!$C$10*Operating!$C$11*Operating!$C$12*$B$8)*(1-Operating!$C$14)-Operating!$C$10*Operating!$C$13-Operating!$C$16)-MAX(0,((Operating!$C$10*Operating!$C$11*Operating!$C$12*$B$8)*(1-Operating!$C$14)-Operating!$C$10*Operating!$C$13-Operating!$C$16))*Operating!$C$15)+Operating!$C$16-Operating!$C$17-Operating!$C$18-Operating!$C$19)*Operating!$B$5-Operating!$C$20+IF(1=Operating!$B$7,Operating!$B$6,0))/(1+E7)^1 -> 89.285714 | D19: =(((((Operating!$D$10*Operating!$D$11*Operating!$D$12*$B$8)*(1-Operating!$D$14)-Operating!$D$10*Operating!$D$13-Operating!$D$16)-MAX(0,((Operating!$D$10*Operating!$D$11*Operating!$D$12*$B$8)*(1-Operating!$D$14)-Operating!$D$10*Operating!$D$13-Operating!$D$16))*Operating!$D$15)+Operating!$D$16-Operating!$D$17-Operating!$D$18-Operating!$D$19)*Operating!$B$5-Operating!$D$20+IF(2=Operating!$B$7,Operating!$B$6,0))/(1+E7)^2 -> 59.789541
A20: Driver 1.0× / rate column 1 | C20: =(((((Operating!$C$10*Operating!$C$11*Operating!$C$12*$B$9)*(1-Operating!$C$14)-Operating!$C$10*Operating!$C$13-Operating!$C$16)-MAX(0,((Operating!$C$10*Operating!$C$11*Operating!$C$12*$B$9)*(1-Operating!$C$14)-Operating!$C$10*Operating!$C$13-Operating!$C$16))*Operating!$C$15)+Operating!$C$16-Operating!$C$17-Operating!$C$18-Operating!$C$19)*Operating!$B$5-Operating!$C$20+IF(1=Operating!$B$7,Operating!$B$6,0))/(1+C7)^1 -> 162.03704 | D20: =(((((Operating!$D$10*Operating!$D$11*Operating!$D$12*$B$9)*(1-Operating!$D$14)-Operating!$D$10*Operating!$D$13-Operating!$D$16)-MAX(0,((Operating!$D$10*Operating!$D$11*Operating!$D$12*$B$9)*(1-Operating!$D$14)-Operating!$D$10*Operating!$D$13-Operating!$D$16))*Operating!$D$15)+Operating!$D$16-Operating!$D$17-Operating!$D$18-Operating!$D$19)*Operating!$B$5-Operating!$D$20+IF(2=Operating!$B$7,Operating!$B$6,0))/(1+C7)^2 -> 128.60082
A21: Driver 1.0× / rate column 2 | C21: =(((((Operating!$C$10*Operating!$C$11*Operating!$C$12*$B$9)*(1-Operating!$C$14)-Operating!$C$10*Operating!$C$13-Operating!$C$16)-MAX(0,((Operating!$C$10*Operating!$C$11*Operating!$C$12*$B$9)*(1-Operating!$C$14)-Operating!$C$10*Operating!$C$13-Operating!$C$16))*Operating!$C$15)+Operating!$C$16-Operating!$C$17-Operating!$C$18-Operating!$C$19)*Operating!$B$5-Operating!$C$20+IF(1=Operating!$B$7,Operating!$B$6,0))/(1+D7)^1 -> 159.09091 | D21: =(((((Operating!$D$10*Operating!$D$11*Operating!$D$12*$B$9)*(1-Operating!$D$14)-Operating!$D$10*Operating!$D$13-Operating!$D$16)-MAX(0,((Operating!$D$10*Operating!$D$11*Operating!$D$12*$B$9)*(1-Operating!$D$14)-Operating!$D$10*Operating!$D$13-Operating!$D$16))*Operating!$D$15)+Operating!$D$16-Operating!$D$17-Operating!$D$18-Operating!$D$19)*Operating!$B$5-Operating!$D$20+IF(2=Operating!$B$7,Operating!$B$6,0))/(1+D7)^2 -> 123.96694
A22: Driver 1.0× / rate column 3 | C22: =(((((Operating!$C$10*Operating!$C$11*Operating!$C$12*$B$9)*(1-Operating!$C$14)-Operating!$C$10*Operating!$C$13-Operating!$C$16)-MAX(0,((Operating!$C$10*Operating!$C$11*Operating!$C$12*$B$9)*(1-Operating!$C$14)-Operating!$C$10*Operating!$C$13-Operating!$C$16))*Operating!$C$15)+Operating!$C$16-Operating!$C$17-Operating!$C$18-Operating!$C$19)*Operating!$B$5-Operating!$C$20+IF(1=Operating!$B$7,Operating!$B$6,0))/(1+E7)^1 -> 156.25 | D22: =(((((Operating!$D$10*Operating!$D$11*Operating!$D$12*$B$9)*(1-Operating!$D$14)-Operating!$D$10*Operating!$D$13-Operating!$D$16)-MAX(0,((Operating!$D$10*Operating!$D$11*Operating!$D$12*$B$9)*(1-Operating!$D$14)-Operating!$D$10*Operating!$D$13-Operating!$D$16))*Operating!$D$15)+Operating!$D$16-Operating!$D$17-Operating!$D$18-Operating!$D$19)*Operating!$B$5-Operating!$D$20+IF(2=Operating!$B$7,Operating!$B$6,0))/(1+E7)^2 -> 119.57908
A23: Driver 1.2× / rate column 1 | C23: =(((((Operating!$C$10*Operating!$C$11*Operating!$C$12*$B$10)*(1-Operating!$C$14)-Operating!$C$10*Operating!$C$13-Operating!$C$16)-MAX(0,((Operating!$C$10*Operating!$C$11*Operating!$C$12*$B$10)*(1-Operating!$C$14)-Operating!$C$10*Operating!$C$13-Operating!$C$16))*Operating!$C$15)+Operating!$C$16-Operating!$C$17-Operating!$C$18-Operating!$C$19)*Operating!$B$5-Operating!$C$20+IF(1=Operating!$B$7,Operating!$B$6,0))/(1+C7)^1 -> 231.48148 | D23: =(((((Operating!$D$10*Operating!$D$11*Operating!$D$12*$B$10)*(1-Operating!$D$14)-Operating!$D$10*Operating!$D$13-Operating!$D$16)-MAX(0,((Operating!$D$10*Operating!$D$11*Operating!$D$12*$B$10)*(1-Operating!$D$14)-Operating!$D$10*Operating!$D$13-Operating!$D$16))*Operating!$D$15)+Operating!$D$16-Operating!$D$17-Operating!$D$18-Operating!$D$19)*Operating!$B$5-Operating!$D$20+IF(2=Operating!$B$7,Operating!$B$6,0))/(1+C7)^2 -> 192.90123
A24: Driver 1.2× / rate column 2 | C24: =(((((Operating!$C$10*Operating!$C$11*Operating!$C$12*$B$10)*(1-Operating!$C$14)-Operating!$C$10*Operating!$C$13-Operating!$C$16)-MAX(0,((Operating!$C$10*Operating!$C$11*Operating!$C$12*$B$10)*(1-Operating!$C$14)-Operating!$C$10*Operating!$C$13-Operating!$C$16))*Operating!$C$15)+Operating!$C$16-Operating!$C$17-Operating!$C$18-Operating!$C$19)*Operating!$B$5-Operating!$C$20+IF(1=Operating!$B$7,Operating!$B$6,0))/(1+D7)^1 -> 227.27273 | D24: =(((((Operating!$D$10*Operating!$D$11*Operating!$D$12*$B$10)*(1-Operating!$D$14)-Operating!$D$10*Operating!$D$13-Operating!$D$16)-MAX(0,((Operating!$D$10*Operating!$D$11*Operating!$D$12*$B$10)*(1-Operating!$D$14)-Operating!$D$10*Operating!$D$13-Operating!$D$16))*Operating!$D$15)+Operating!$D$16-Operating!$D$17-Operating!$D$18-Operating!$D$19)*Operating!$B$5-Operating!$D$20+IF(2=Operating!$B$7,Operating!$B$6,0))/(1+D7)^2 -> 185.95041
A25: Driver 1.2× / rate column 3 | C25: =(((((Operating!$C$10*Operating!$C$11*Operating!$C$12*$B$10)*(1-Operating!$C$14)-Operating!$C$10*Operating!$C$13-Operating!$C$16)-MAX(0,((Operating!$C$10*Operating!$C$11*Operating!$C$12*$B$10)*(1-Operating!$C$14)-Operating!$C$10*Operating!$C$13-Operating!$C$16))*Operating!$C$15)+Operating!$C$16-Operating!$C$17-Operating!$C$18-Operating!$C$19)*Operating!$B$5-Operating!$C$20+IF(1=Operating!$B$7,Operating!$B$6,0))/(1+E7)^1 -> 223.21429 | D25: =(((((Operating!$D$10*Operating!$D$11*Operating!$D$12*$B$10)*(1-Operating!$D$14)-Operating!$D$10*Operating!$D$13-Operating!$D$16)-MAX(0,((Operating!$D$10*Operating!$D$11*Operating!$D$12*$B$10)*(1-Operating!$D$14)-Operating!$D$10*Operating!$D$13-Operating!$D$16))*Operating!$D$15)+Operating!$D$16-Operating!$D$17-Operating!$D$18-Operating!$D$19)*Operating!$B$5-Operating!$D$20+IF(2=Operating!$B$7,Operating!$B$6,0))/(1+E7)^2 -> 179.36862

Sheet Checks
A1: demo-mine / Checks
A5: Valid active scenario | B5: =IF(OR(Assumptions!B4="bear",Assumptions!B4="base",Assumptions!B4="bull"),"PASS","FAIL") -> PASS
A6: Positive diluted shares | B6: =IF(Assumptions!$B$10>0,"PASS","FAIL") -> PASS
A7: Equity bridge reconciliation | B7: =IF(ABS(Valuation!B9-(Valuation!B5+Valuation!B6+Valuation!B7-Valuation!B8))<0.01,"PASS","FAIL") -> PASS
A8: Central sensitivity reconciliation | B8: =IF(ABS(Sensitivities!D9-Valuation!B11)<0.000001,"PASS","FAIL") -> PASS
A9: Reference quote pair | B9: =IF(OR(AND(Assumptions!$B$11="",Assumptions!$B$13=""),AND(ISNUMBER(Assumptions!$B$11),Assumptions!$B$11>0,Assumptions!$B$13<>"")),"PASS","FAIL") -> PASS
A10: Ownership range | B10: =IF(AND(Operating!$B$5>=0,Operating!$B$5<=1),"PASS","FAIL") -> PASS
A13: Workbook checks are structural, not evidence approval. Import validates all scenarios, declared units, formula integrity and financial constraints independently. Any formula changes require a new model design review.

Sheet Readme
A1: demo-mine / Readme
A5: WORKFLOW | Read the Markdown memo first. Excel is the editable detailed model. Change blue assumptions, recalculate, save and import to create a new validated research snapshot. Existing snapshots remain immutable.
A9: MODEL | One active scenario drives all formulas. Select bear/base/bull in Assumptions!B4. Forecast horizons are fixed by the source model; shorter cases have zero inputs after their final period.
A13: UNITS | Calculations use absolute currency amounts, not millions. Input provenance comments identify unit, source, author and rationale. Historical rows retain original reported units; normalize before using them in assumptions.
A17: OWNERSHIP | Whole-operation cash flow is multiplied by ownership once. Corporate costs and residual value are company-attributable. Cash, debt and other assets are added at company level.
A21: METHOD | Annual end-period discounting; explicit residual only. Positive EBIT tax floor; no deferred tax or loss carryforwards. Cash excludes debt repayment, funding and dividends. This is not an integrated income statement, balance sheet and cash-flow forecast.
A25: EDITING | Blue inputs are editable. Green formulas link sheets. Black formulas calculate locally. Keep formulas and metadata intact. Synchronization records changed inputs as analyst overrides. Explain their source and rationale in the research memo; formula edits are rejected.
A29: EVIDENCE | A professional workbook layout does not upgrade uncertain evidence. Missing current quotes, mine-life support, payable sales or capital structure remain research gaps. Model values are not recommendations.
A33: KNOWN LIMITATIONS

Sheet _Model
A1: investing-excel-v1
A2: {"schema_version":1,"baseline":{"company_id":"demo-mine","model_type":"finite_mine","currency":"AUD","valuation_date":"2026-09-20","quote_date":"2026-09-18","cash":100,"debt":20.0,"other_assets":0.0,"diluted_shares":100.0,"reference_price":2.0,"synthetic":true,"historical":[],"scenarios":{"bear":{"discount_rate":0.1,"ownership":0.5,"ownership_basis":"whole_operation","residual_value":0.0,"years":[{"year":2027,"payable_tonnes":10.0,"price":80.0,"price_currency":"USD","fx":1.0,"unit_cost":40.0,"royalty_rate":0.0,"tax_rate":0.25,"depreciation":0.0,"capex":100.0,"working_capital_change":0.0,"closure":0.0,"corporate_cost":0.0},{"year":2028,"payable_tonnes":10.0,"price":80.0,"price_currency":"USD","fx":1.0,"unit_cost":40.0,"royalty_rate":0.0,"tax_rate":0.25,"depreciation":0.0,"capex":100.0,"working_capital_change":0.0,"closure":50.0,"corporate_cost":0.0}]},"base":{"discount_rate":0.1,"ownership":0.5,"ownership_basis":"whole_operation","residual_value":0.0,"years":[{"year":2027,"payable_tonnes":10.0,"price":100.0,"price_currency":"USD","fx":1.0,"unit_cost":40.0,"royalty_rate":0.0,"tax_rate":0.25,"depreciation":0.0,"capex":100.0,"working_capital_change":0.0,"closure":0.0,"corporate_cost":0.0},{"year":2028,"payable_tonnes":10.0,"price":100.0,"price_currency":"USD","fx":1.0,"unit_cost":40.0,"royalty_rate":0.0,"tax_rate":0.25,"depreciation":0.0,"capex":100.0,"working_capital_change":0.0,"closure":50.0,"corporate_cost":0.0}]},"bull":{"discount_rate":0.1,"ownership":0.5,"ownership_basis":"whole_operation","residual_value":0.0,"years":[{"year":2027,"payable_tonnes":10.0,"price":120.0,"price_currency":"USD","fx":1.0,"unit_cost":40.0,"royalty_rate":0.0,"tax_rate":0.25,"depreciation":0.0,"capex":100.0,"working_capital_change":0.0,"closure":0.0,"corporate_cost":0.0},{"year":2028,"payable_tonnes":10.0,"price":120.0,"price_currency":"USD","fx":1.0,"unit_cost":40.0,"royalty_rate":0.0,"tax_rate":0.25,"depreciation":0.0,"capex":100.0,"working_capital_change":0.0,"closure":50.0,"corporate_cost":0.0}]}},"provenance":{"/cash":{"unit":"AUD","rationale":"Synthetic teaching fixture; not reported company data","author":"example fixture","source":"synthetic://example"},"/debt":{"unit":"AUD","rationale":"Synthetic teaching fixture; not reported company data","author":"example fixture","source":"synthetic://example"},"/other_assets":{"unit":"AUD","rationale":"Synthetic teaching fixture; not reported company data","author":"example fixture","source":"synthetic://example"},"/diluted_shares":{"unit":"shares","rationale":"Synthetic teaching fixture; not reported company data","author":"example fixture","source":"synthetic://example"},"/reference_price":{"unit":"AUD/share","rationale":"Synthetic teaching fixture; not reported company data","author":"example fixture","source":"synthetic://example"},"/scenarios/bear/discount_rate":{"unit":"fraction","rationale":"Synthetic teaching fixture; not reported company data","author":"example fixture","source":"synthetic://example"},"/scenarios/bear/ownership":{"unit":"fraction","rationale":"Synthetic teaching fixture; not reported company data","author":"example fixture","source":"synthetic://example"},"/scenarios/bear/residual_value":{"unit":"AUD","rationale":"Synthetic teaching fixture; not reported company data","author":"example fixture","source":"synthetic://example"},"/scenarios/bear/years/0/payable_tonnes":{"unit":"tonnes","rationale":"Synthetic teaching fixture; not reported company data","author":"example fixture","source":"synthetic://example"},"/scenarios/bear/years/0/price":{"unit":"USD/tonne","rationale":"Synthetic teaching fixture; not reported company data","author":"example fixture","source":"synthetic://example"},"/scenarios/bear/years/0/fx":{"unit":"AUD/USD","rationale":"Synthetic teaching fixture; not reported company data","author":"example fixture","source":"synthetic://example"},"/scenarios/bear/years/0/unit_cost":{"unit":"AUD/tonne","rationale":"Synthetic teaching fixture; not reported company data","author":"example fixture","source":"synthetic://example"},"/scenarios/bear/years/0/royalty_rate":{"unit":"fraction","rationale":"Synthetic teaching fixture; not reported company data","author":"example fixture","source":"synthetic://example"},"/scenarios/bear/years/0/tax_rate":{"unit":"fraction","rationale":"Synthetic teaching fixture; not reported company data","author":"example fixture","source":"synthetic://example"},"/scenarios/bear/years/0/depreciation":{"unit":"AUD","rationale":"Synthetic teaching fixture; not reported company data","author":"example fixture","source":"synthetic://example"},"/scenarios/bear/years/0/capex":{"unit":"AUD","rationale":"Synthetic teaching fixture; not reported company data","author":"example fixture","source":"synthetic://example"},"/scenarios/bear/years/0/working_capital_change":{"unit":"AUD","rationale":"Synthetic teaching fixture; not reported company data","author":"example fixture","source":"synthetic://example"},"/scenarios/bear/years/0/closure":{"unit":"AUD","rationale":"Synthetic teaching fixture; not reported company data","author":"example fixture","source":"synthetic://example"},"/scenarios/bear/years/0/corporate_cost":{"unit":"AUD","rationale":"Synthetic teaching fixture; not reported company data","author":"example fixture","source":"synthetic://example"},"/scenarios/bear/years/1/payable_tonnes":{"unit":"tonnes","rationale":"Synthetic teaching fixture; not reported company data","author":"example fixture","source":"synthetic://example"},"/scenarios/bear/years/1/price":{"unit":"USD/tonne","rationale":"Synthetic teaching fixture; not reported company data","author":"example fixture","source":"synthetic://example"},"/scenarios/bear/years/1/fx":{"unit":"AUD/USD","rationale":"Synthetic teaching fixture; not reported company data","author":"example fixture","source":"synthetic://example"},"/scenarios/bear/years/1/unit_cost":{"unit":"AUD/tonne","rationale":"Synthetic teaching fixture; not reported company data","author":"example fixture","source":"synthetic://example"},"/scenarios/bear/years/1/royalty_rate":{"unit":"fraction","rationale":"Synthetic teaching fixture; not reported company data","author":"example fixture","source":"synthetic://example"},"/scenarios/bear/years/1/tax_rate":{"unit":"fraction","rationale":"Synthetic teaching fixture; not reported company data","author":"example fixture","source":"synthetic://example"},"/scenarios/bear/years/1/depreciation":{"unit":"AUD","rationale":"Synthetic teaching fixture; not reported company data","author":"example fixture","source":"synthetic://example"},"/scenarios/bear/years/1/capex":{"unit":"AUD","rationale":"Synthetic teaching fixture; not reported company data","author":"example fixture","source":"synthetic://example"},"/scenarios/bear/years/1/working_capital_change":{"unit":"AUD","rationale":"Synthetic teaching fixture; not reported company data","author":"example fixture","source":"synthetic://example"},"/scenarios/bear/years/1/closure":{"unit":"AUD","rationale":"Synthetic teaching fixture; not reported company data","author":"example fixture","source":"synthetic://example"},"/scenarios/bear/years/1/corporate_cost":{"unit":"AUD","rationale":"Synthetic teaching fixture; not reported company data","author":"example fixture","source":"synthetic://example"},"/scenarios/base/discount_rate":{"unit":"fraction","rationale":"Synthetic teaching fixture; not reported company data","author":"example fixture","source":"synthetic://example"},"/scenarios/base/ownership":{"unit":"fraction","rationale":"Synthetic teaching fixture; not reported company data","author":"example fixture","source":"synthetic://example"},"/scenarios/base/residual_value":{"unit":"AUD","rationale":"Synthetic teaching fixture; not reported company data","author":"example fixture","source":"synthetic://example"},"/scenarios/base/years/0/payable_tonnes":{"unit":"tonnes","rationale":"Synthetic teaching fixture; not reported company data","author":"example fixture","source":"synthetic://example"},"/scenarios/base/years/0/price":{"unit":"USD/tonne","rationale":"Synthetic teaching fixture; not reported company data","author":"example fixture","source":"synthetic://example"},"/scenarios/base/years/0/fx":{"unit":"AUD/USD","rationale":"Synthetic teaching fixture; not reported company data","author":"example fixture","source":"synthetic://example"},"/scenarios/base/years/0/unit_cost":{"unit":"AUD/tonne","rationale":"Synthetic teaching fixture; not reported company data","author":"example fixture","source":"synthetic://example"},"/scenarios/base/years/0/royalty_rate":{"unit":"fraction","rationale":"Synthetic teaching fixture; not reported company data","author":"example fixture","source":"synthetic://example"},"/scenarios/base/years/0/tax_rate":{"unit":"fraction","rationale":"Synthetic teaching fixture; not reported company data","author":"example fixture","source":"synthetic://example"},"/scenarios/base/years/0/depreciation":{"unit":"AUD","rationale":"Synthetic teaching fixture; not reported company data","author":"example fixture","source":"synthetic://example"},"/scenarios/base/years/0/capex":{"unit":"AUD","rationale":"Synthetic teaching fixture; not reported company data","author":"example fixture","source":"synthetic://example"},"/scenarios/base/years/0/working_capital_change":{"unit":"AUD","rationale":"Synthetic teaching fixture; not reported company data","author":"example fixture","source":"synthetic://example"},"/scenarios/base/years/0/closure":{"unit":"AUD","rationale":"Synthetic teaching fixture; not reported company data","author":"example fixture","source":"synthetic://example"},"/scenarios/base/years/0/corporate_cost":{"unit":"AUD","rationale":"Synthetic teaching fixture; not reported company data","author":"example fixture","source":"synthetic://example"},"/scenarios/base/years/1/payable_tonnes":{"unit":"tonnes","rationale":"Synthetic teaching fixture; not reported company data","author":"example fixture","source":"synthetic://example"},"/scenarios/base/years/1/price":{"unit":"USD/tonne","rationale":"Synthetic teaching fixture; not reported company data","author":"example fixture","source":"synthetic://example"},"/scenarios/base/years/1/fx":{"unit":"AUD/USD","rationale":"Synthetic teaching fixture; not reported company data","author":"example fixture","source":"synthetic://example"},"/scenarios/base/years/1/unit_cost":{"unit":"AUD/tonne","rationale":"Synthetic teaching fixture; not reported company data","author":"example fixture","source":"synthetic://example"},"/scenarios/base/years/1/royalty_rate":{"unit":"fraction","rationale":"Synthetic teaching fixture; not reported company data","author":"example fixture","source":"synthetic://example"},"/scenarios/base/years/1/tax_rate":{"unit":"fraction","rationale":"Synthetic teaching fixture; not reported company data","author":"example fixture","source":"synthetic://example"},"/scenarios/base/years/1/depreciation":{"unit":"AUD","rationale":"Synthetic teaching fixture; not reported company data","author":"example fixture","source":"synthetic://example"},"/scenarios/base/years/1/capex":{"unit":"AUD","rationale":"Synthetic teaching fixture; not reported company data","author":"example fixture","source":"synthetic://example"},"/scenarios/base/years/1/working_capital_change":{"unit":"AUD","rationale":"Synthetic teaching fixture; not reported company data","author":"example fixture","source":"synthetic://example"},"/scenarios/base/years/1/closure":{"unit":"AUD","rationale":"Synthetic teaching fixture; not reported company data","author":"example fixture","source":"synthetic://example"},"/scenarios/base/years/1/corporate_cost":{"unit":"AUD","rationale":"Synthetic teaching fixture; not reported company data","author":"example fixture","source":"synthetic://example"},"/scenarios/bull/discount_rate":{"unit":"fraction","rationale":"Synthetic teaching fixture; not reported company data","author":"example fixture","source":"synthetic://example"},"/scenarios/bull/ownership":{"unit":"fraction","rationale":"Synthetic teaching fixture; not reported company data","author":"example fixture","source":"synthetic://example"},"/scenarios/bull/residual_value":{"unit":"AUD","rationale":"Synthetic teaching fixture; not reported company data","author":"example fixture","source":"synthetic://example"},"/scenarios/bull/years/0/payable_tonnes":{"unit":"tonnes","rationale":"Synthetic teaching fixture; not reported company data","author":"example fixture","source":"synthetic://example"},"/scenarios/bull/years/0/price":{"unit":"USD/tonne","rationale":"Synthetic teaching fixture; not reported company data","author":"example fixture","source":"synthetic://example"},"/scenarios/bull/years/0/fx":{"unit":"AUD/USD","rationale":"Synthetic teaching fixture; not reported company data","author":"example fixture","source":"synthetic://example"},"/scenarios/bull/years/0/unit_cost":{"unit":"AUD/tonne","rationale":"Synthetic teaching fixture; not reported company data","author":"example fixture","source":"synthetic://example"},"/scenarios/bull/years/0/royalty_rate":{"unit":"fraction","rationale":"Synthetic teaching fixture; not reported company data","author":"example fixture","source":"synthetic://example"},"/scenarios/bull/years/0/tax_rate":{"unit":"fraction","rationale":"Synthetic teaching fixture; not reported company data","author":"example fixture","source":"synthetic://example"},"/scenarios/bull/years/0/depreciation":{"unit":"AUD","rationale":"Synthetic teaching fixture; not reported company data","author":"example fixture","source":"synthetic://example"},"/scenarios/bull/years/0/capex":{"unit":"AUD","rationale":"Synthetic teaching fixture; not reported company data","author":"example fixture","source":"synthetic://example"},"/scenarios/bull/years/0/working_capital_change":{"unit":"AUD","rationale":"Synthetic teaching fixture; not reported company data","author":"example fixture","source":"synthetic://example"},"/scenarios/bull/years/0/closure":{"unit":"AUD","rationale":"Synthetic teaching fixture; not reported company data","author":"example fixture","source":"synthetic://example"},"/scenarios/bull/years/0/corporate_cost":{"unit":"AUD","rationale":"Synthetic teaching fixture; not reported company data","author":"example fixture","source":"synthetic://example"},"/scenarios/bull/years/1/payable_tonnes":{"unit":"tonnes","rationale":"Synthetic teaching fixture; not reported company data","author":"example fixture","source":"synthetic://example"},"/scenarios/bull/years/1/price":{"unit":"USD/tonne","rationale":"Synthetic teaching fixture; not reported company data","author":"example fixture","source":"synthetic://example"},"/scenarios/bull/years/1/fx":{"unit":"AUD/USD","rationale":"Synthetic teaching fixture; not reported company data","author":"example fixture","source":"synthetic://example"},"/scenarios/bull/years/1/unit_cost":{"unit":"AUD/tonne","rationale":"Synthetic teaching fixture; not reported company data","author":"example fixture","source":"synthetic://example"},"/scenarios/bull/years/1/royalty_rate":{"unit":"fraction","rationale":"Synthetic teaching fixture; not reported company data","author":"example fixture","source":"synthetic://example"},"/scenarios/bull/years/1/tax_rate":{"unit":"fraction","rationale":"Synthetic teaching fixture; not reported company data","author":"example fixture","source":"synthetic://example"},"/scenarios/bull/years/1/depreciation":{"unit":"AUD","rationale":"Synthetic teaching fixture; not reported company data","author":"example fixture","source":"synthetic://example"},"/scenarios/bull/years/1/capex":{"unit":"AUD","rationale":"Synthetic teaching fixture; not reported company data","author":"example fixture","source":"synthetic://example"},"/scenarios/bull/years/1/working_capital_change":{"unit":"AUD","rationale":"Synthetic teaching fixture; not reported company data","author":"example fixture","source":"synthetic://example"},"/scenarios/bull/years/1/closure":{"unit":"AUD","rationale":"Synthetic teaching fixture; not reported company data","author":"example fixture","source":"synthetic://example"},"/scenarios/bull/years/1/corporate_cost":{"unit":"AUD","rationale":"Synthetic teaching fixture; not reported company data","author":"example fixture","source":"synthetic://example"}}},"inputs":{"/cash":{"sheet":"Assumptions","cell":"B7"},"/debt":{"sheet":"Assumptions","cell":"B8"},"/other_assets":{"sheet":"Assumptions","cell":"B9"},"/diluted_shares":{"sheet":"Assumptions","cell":"B10"},"/reference_price":{"sheet":"Assumptions","cell":"B11"},"/valuation_date":{"sheet":"Assumptions","cell":"B12"},"/quote_date":{"sheet":"Assumptions","cell":"B13"},"/scenarios/bear/discount_rate":{"sheet":"Assumptions","cell":"B20"},"/scenarios/bear/ownership":{"sheet":"Assumptions","cell":"B21"},"/scenarios/bear/residual_value":{"sheet":"Assumptions","cell":"B22"},"/scenarios/bear/years/0/payable_tonnes":{"sheet":"Assumptions","cell":"C25"},"/scenarios/bear/years/1/payable_tonnes":{"sheet":"Assumptions","cell":"D25"},"/scenarios/bear/years/0/price":{"sheet":"Assumptions","cell":"C26"},"/scenarios/bear/years/1/price":{"sheet":"Assumptions","cell":"D26"},"/scenarios/bear/years/0/fx":{"sheet":"Assumptions","cell":"C27"},"/scenarios/bear/years/1/fx":{"sheet":"Assumptions","cell":"D27"},"/scenarios/bear/years/0/unit_cost":{"sheet":"Assumptions","cell":"C28"},"/scenarios/bear/years/1/unit_cost":{"sheet":"Assumptions","cell":"D28"},"/scenarios/bear/years/0/royalty_rate":{"sheet":"Assumptions","cell":"C29"},"/scenarios/bear/years/1/royalty_rate":{"sheet":"Assumptions","cell":"D29"},"/scenarios/bear/years/0/tax_rate":{"sheet":"Assumptions","cell":"C30"},"/scenarios/bear/years/1/tax_rate":{"sheet":"Assumptions","cell":"D30"},"/scenarios/bear/years/0/depreciation":{"sheet":"Assumptions","cell":"C31"},"/scenarios/bear/years/1/depreciation":{"sheet":"Assumptions","cell":"D31"},"/scenarios/bear/years/0/capex":{"sheet":"Assumptions","cell":"C32"},"/scenarios/bear/years/1/capex":{"sheet":"Assumptions","cell":"D32"},"/scenarios/bear/years/0/working_capital_change":{"sheet":"Assumptions","cell":"C33"},"/scenarios/bear/years/1/working_capital_change":{"sheet":"Assumptions","cell":"D33"},"/scenarios/bear/years/0/closure":{"sheet":"Assumptions","cell":"C34"},"/scenarios/bear/years/1/closure":{"sheet":"Assumptions","cell":"D34"},"/scenarios/bear/years/0/corporate_cost":{"sheet":"Assumptions","cell":"C35"},"/scenarios/bear/years/1/corporate_cost":{"sheet":"Assumptions","cell":"D35"},"/scenarios/base/discount_rate":{"sheet":"Assumptions","cell":"B39"},"/scenarios/base/ownership":{"sheet":"Assumptions","cell":"B40"},"/scenarios/base/residual_value":{"sheet":"Assumptions","cell":"B41"},"/scenarios/base/years/0/payable_tonnes":{"sheet":"Assumptions","cell":"C44"},"/scenarios/base/years/1/payable_tonnes":{"sheet":"Assumptions","cell":"D44"},"/scenarios/base/years/0/price":{"sheet":"Assumptions","cell":"C45"},"/scenarios/base/years/1/price":{"sheet":"Assumptions","cell":"D45"},"/scenarios/base/years/0/fx":{"sheet":"Assumptions","cell":"C46"},"/scenarios/base/years/1/fx":{"sheet":"Assumptions","cell":"D46"},"/scenarios/base/years/0/unit_cost":{"sheet":"Assumptions","cell":"C47"},"/scenarios/base/years/1/unit_cost":{"sheet":"Assumptions","cell":"D47"},"/scenarios/base/years/0/royalty_rate":{"sheet":"Assumptions","cell":"C48"},"/scenarios/base/years/1/royalty_rate":{"sheet":"Assumptions","cell":"D48"},"/scenarios/base/years/0/tax_rate":{"sheet":"Assumptions","cell":"C49"},"/scenarios/base/years/1/tax_rate":{"sheet":"Assumptions","cell":"D49"},"/scenarios/base/years/0/depreciation":{"sheet":"Assumptions","cell":"C50"},"/scenarios/base/years/1/depreciation":{"sheet":"Assumptions","cell":"D50"},"/scenarios/base/years/0/capex":{"sheet":"Assumptions","cell":"C51"},"/scenarios/base/years/1/capex":{"sheet":"Assumptions","cell":"D51"},"/scenarios/base/years/0/working_capital_change":{"sheet":"Assumptions","cell":"C52"},"/scenarios/base/years/1/working_capital_change":{"sheet":"Assumptions","cell":"D52"},"/scenarios/base/years/0/closure":{"sheet":"Assumptions","cell":"C53"},"/scenarios/base/years/1/closure":{"sheet":"Assumptions","cell":"D53"},"/scenarios/base/years/0/corporate_cost":{"sheet":"Assumptions","cell":"C54"},"/scenarios/base/years/1/corporate_cost":{"sheet":"Assumptions","cell":"D54"},"/scenarios/bull/discount_rate":{"sheet":"Assumptions","cell":"B58"},"/scenarios/bull/ownership":{"sheet":"Assumptions","cell":"B59"},"/scenarios/bull/residual_value":{"sheet":"Assumptions","cell":"B60"},"/scenarios/bull/years/0/payable_tonnes":{"sheet":"Assumptions","cell":"C63"},"/scenarios/bull/years/1/payable_tonnes":{"sheet":"Assumptions","cell":"D63"},"/scenarios/bull/years/0/price":{"sheet":"Assumptions","cell":"C64"},"/scenarios/bull/years/1/price":{"sheet":"Assumptions","cell":"D64"},"/scenarios/bull/years/0/fx":{"sheet":"Assumptions","cell":"C65"},"/scenarios/bull/years/1/fx":{"sheet":"Assumptions","cell":"D65"},"/scenarios/bull/years/0/unit_cost":{"sheet":"Assumptions","cell":"C66"},"/scenarios/bull/years/1/unit_cost":{"sheet":"Assumptions","cell":"D66"},"/scenarios/bull/years/0/royalty_rate":{"sheet":"Assumptions","cell":"C67"},"/scenarios/bull/years/1/royalty_rate":{"sheet":"Assumptions","cell":"D67"},"/scenarios/bull/years/0/tax_rate":{"sheet":"Assumptions","cell":"C68"},"/scenarios/bull/years/1/tax_rate":{"sheet":"Assumptions","cell":"D68"},"/scenarios/bull/years/0/depreciation":{"sheet":"Assumptions","cell":"C69"},"/scenarios/bull/years/1/depreciation":{"sheet":"Assumptions","cell":"D69"},"/scenarios/bull/years/0/capex":{"sheet":"Assumptions","cell":"C70"},"/scenarios/bull/years/1/capex":{"sheet":"Assumptions","cell":"D70"},"/scenarios/bull/years/0/working_capital_change":{"sheet":"Assumptions","cell":"C71"},"/scenarios/bull/years/1/working_capital_change":{"sheet":"Assumptions","cell":"D71"},"/scenarios/bull/years/0/closure":{"sheet":"Assumptions","cell":"C72"},"/scenarios/bull/years/1/closure":{"sheet":"Assumptions","cell":"D72"},"/scenarios/bull/years/0/corporate_cost":{"sheet":"Assumptions","cell":"C73"},"/scenarios/bull/years/1/corporate_cost":{"sheet":"Assumptions","cell":"D73"}},"outputs":{"active_case":{"sheet":"Assumptions","cell":"B4"},"years/0/year":{"sheet":"Operating","cell":"C9"},"years/0/revenue":{"sheet":"Operating","cell":"C23"},"years/0/operating_cost":{"sheet":"Operating","cell":"C24"},"years/0/royalties":{"sheet":"Operating","cell":"C25"},"years/0/ebit":{"sheet":"Operating","cell":"C26"},"years/0/tax":{"sheet":"Operating","cell":"C27"},"years/0/nopat":{"sheet":"Operating","cell":"C28"},"years/0/operating_fcf":{"sheet":"Operating","cell":"C29"},"years/0/fcf":{"sheet":"Operating","cell":"C30"},"years/0/present_value":{"sheet":"Operating","cell":"C31"},"years/0/illustrative_cash":{"sheet":"Operating","cell":"C32"},"years/1/year":{"sheet":"Operating","cell":"D9"},"years/1/revenue":{"sheet":"Operating","cell":"D23"},"years/1/operating_cost":{"sheet":"Operating","cell":"D24"},"years/1/royalties":{"sheet":"Operating","cell":"D25"},"years/1/ebit":{"sheet":"Operating","cell":"D26"},"years/1/tax":{"sheet":"Operating","cell":"D27"},"years/1/nopat":{"sheet":"Operating","cell":"D28"},"years/1/operating_fcf":{"sheet":"Operating","cell":"D29"},"years/1/fcf":{"sheet":"Operating","cell":"D30"},"years/1/present_value":{"sheet":"Operating","cell":"D31"},"years/1/illustrative_cash":{"sheet":"Operating","cell":"D32"},"enterprise_value":{"sheet":"Valuation","cell":"B5"},"cash":{"sheet":"Valuation","cell":"B6"},"other_assets":{"sheet":"Valuation","cell":"B7"},"debt":{"sheet":"Valuation","cell":"B8"},"equity_value":{"sheet":"Valuation","cell":"B9"},"diluted_shares":{"sheet":"Valuation","cell":"B10"},"per_share":{"sheet":"Valuation","cell":"B11"},"minimum_illustrative_cash":{"sheet":"Valuation","cell":"B12"},"discount_rate/0":{"sheet":"Sensitivities","cell":"C7"},"discount_rate/1":{"sheet":"Sensitivities","cell":"D7"},"discount_rate/2":{"sheet":"Sensitivities","cell":"E7"},"driver_multiplier/0":{"sheet":"Sensitivities","cell":"B8"},"sensitivity/0/0":{"sheet":"Sensitivities","cell":"C8"},"sensitivity/0/1":{"sheet":"Sensitivities","cell":"D8"},"sensitivity/0/2":{"sheet":"Sensitivities","cell":"E8"},"driver_multiplier/1":{"sheet":"Sensitivities","cell":"B9"},"sensitivity/1/0":{"sheet":"Sensitivities","cell":"C9"},"sensitivity/1/1":{"sheet":"Sensitivities","cell":"D9"},"sensitivity/1/2":{"sheet":"Sensitivities","cell":"E9"},"driver_multiplier/2":{"sheet":"Sensitivities","cell":"B10"},"sensitivity/2/0":{"sheet":"Sensitivities","cell":"C10"},"sensitivity/2/1":{"sheet":"Sensitivities","cell":"D10"},"sensitivity/2/2":{"sheet":"Sensitivities","cell":"E10"},"checks/0":{"sheet":"Checks","cell":"B5"},"checks/1":{"sheet":"Checks","cell":"B6"},"checks/2":{"sheet":"Checks","cell":"B7"},"checks/3":{"sheet":"Checks","cell":"B8"},"checks/4":{"sheet":"Checks","cell":"B9"},"checks/5":{"sheet":"Checks","cell":"B10"}},"formula_cells":{"Operating!B4":"=IF(Assumptions!$B$4=\"bear\",'Assumptions'!$B$20,IF(Assumptions!$B$4=\"base\",'Assumptions'!$B$39,'Assumptions'!$B$58))","Operating!B5":"=IF(Assumptions!$B$4=\"bear\",'Assumptions'!$B$21,IF(Assumptions!$B$4=\"base\",'Assumptions'!$B$40,'Assumptions'!$B$59))","Operating!B6":"=IF(Assumptions!$B$4=\"bear\",'Assumptions'!$B$22,IF(Assumptions!$B$4=\"base\",'Assumptions'!$B$41,'Assumptions'!$B$60))","Operating!B7":"=IF(Assumptions!$B$4=\"bear\",'Assumptions'!$B$23,IF(Assumptions!$B$4=\"base\",'Assumptions'!$B$42,'Assumptions'!$B$61))","Operating!B8":"=IF(Assumptions!$B$4=\"bear\",\"payable_sales\",IF(Assumptions!$B$4=\"base\",\"payable_sales\",\"payable_sales\"))","Operating!C9":"=YEAR(DATEVALUE('Assumptions'!$B$12))+1","Operating!C10":"=IF(Assumptions!$B$4=\"bear\",'Assumptions'!$C$25,IF(Assumptions!$B$4=\"base\",'Assumptions'!$C$44,'Assumptions'!$C$63))","Operating!C11":"=IF(Assumptions!$B$4=\"bear\",'Assumptions'!$C$26,IF(Assumptions!$B$4=\"base\",'Assumptions'!$C$45,'Assumptions'!$C$64))","Operating!C12":"=IF(Assumptions!$B$4=\"bear\",'Assumptions'!$C$27,IF(Assumptions!$B$4=\"base\",'Assumptions'!$C$46,'Assumptions'!$C$65))","Operating!C13":"=IF(Assumptions!$B$4=\"bear\",'Assumptions'!$C$28,IF(Assumptions!$B$4=\"base\",'Assumptions'!$C$47,'Assumptions'!$C$66))","Operating!C14":"=IF(Assumptions!$B$4=\"bear\",'Assumptions'!$C$29,IF(Assumptions!$B$4=\"base\",'Assumptions'!$C$48,'Assumptions'!$C$67))","Operating!C15":"=IF(Assumptions!$B$4=\"bear\",'Assumptions'!$C$30,IF(Assumptions!$B$4=\"base\",'Assumptions'!$C$49,'Assumptions'!$C$68))","Operating!C16":"=IF(Assumptions!$B$4=\"bear\",'Assumptions'!$C$31,IF(Assumptions!$B$4=\"base\",'Assumptions'!$C$50,'Assumptions'!$C$69))","Operating!C17":"=IF(Assumptions!$B$4=\"bear\",'Assumptions'!$C$32,IF(Assumptions!$B$4=\"base\",'Assumptions'!$C$51,'Assumptions'!$C$70))","Operating!C18":"=IF(Assumptions!$B$4=\"bear\",'Assumptions'!$C$33,IF(Assumptions!$B$4=\"base\",'Assumptions'!$C$52,'Assumptions'!$C$71))","Operating!C19":"=IF(Assumptions!$B$4=\"bear\",'Assumptions'!$C$34,IF(Assumptions!$B$4=\"base\",'Assumptions'!$C$53,'Assumptions'!$C$72))","Operating!C20":"=IF(Assumptions!$B$4=\"bear\",'Assumptions'!$C$35,IF(Assumptions!$B$4=\"base\",'Assumptions'!$C$54,'Assumptions'!$C$73))","Operating!C23":"='Operating'!$C$10*'Operating'!$C$11*'Operating'!$C$12","Operating!C24":"='Operating'!$C$10*'Operating'!$C$13","Operating!C25":"='Operating'!$C$23*'Operating'!$C$14","Operating!C26":"='Operating'!$C$23-'Operating'!$C$24-'Operating'!$C$25-'Operating'!$C$16","Operating!C27":"=MAX(0,'Operating'!$C$26)*'Operating'!$C$15","Operating!C28":"='Operating'!$C$26-'Operating'!$C$27","Operating!C29":"='Operating'!$C$28+'Operating'!$C$16-'Operating'!$C$17-'Operating'!$C$18-'Operating'!$C$19","Operating!C30":"='Operating'!$C$29*'Operating'!$B$5-'Operating'!$C$20+IF(1='Operating'!$B$7,'Operating'!$B$6,0)","Operating!C31":"='Operating'!$C$30/(1+'Operating'!$B$4)^1","Operating!C32":"='Assumptions'!$B$7+'Operating'!$C$30","Operating!D9":"=YEAR(DATEVALUE('Assumptions'!$B$12))+2","Operating!D10":"=IF(Assumptions!$B$4=\"bear\",'Assumptions'!$D$25,IF(Assumptions!$B$4=\"base\",'Assumptions'!$D$44,'Assumptions'!$D$63))","Operating!D11":"=IF(Assumptions!$B$4=\"bear\",'Assumptions'!$D$26,IF(Assumptions!$B$4=\"base\",'Assumptions'!$D$45,'Assumptions'!$D$64))","Operating!D12":"=IF(Assumptions!$B$4=\"bear\",'Assumptions'!$D$27,IF(Assumptions!$B$4=\"base\",'Assumptions'!$D$46,'Assumptions'!$D$65))","Operating!D13":"=IF(Assumptions!$B$4=\"bear\",'Assumptions'!$D$28,IF(Assumptions!$B$4=\"base\",'Assumptions'!$D$47,'Assumptions'!$D$66))","Operating!D14":"=IF(Assumptions!$B$4=\"bear\",'Assumptions'!$D$29,IF(Assumptions!$B$4=\"base\",'Assumptions'!$D$48,'Assumptions'!$D$67))","Operating!D15":"=IF(Assumptions!$B$4=\"bear\",'Assumptions'!$D$30,IF(Assumptions!$B$4=\"base\",'Assumptions'!$D$49,'Assumptions'!$D$68))","Operating!D16":"=IF(Assumptions!$B$4=\"bear\",'Assumptions'!$D$31,IF(Assumptions!$B$4=\"base\",'Assumptions'!$D$50,'Assumptions'!$D$69))","Operating!D17":"=IF(Assumptions!$B$4=\"bear\",'Assumptions'!$D$32,IF(Assumptions!$B$4=\"base\",'Assumptions'!$D$51,'Assumptions'!$D$70))","Operating!D18":"=IF(Assumptions!$B$4=\"bear\",'Assumptions'!$D$33,IF(Assumptions!$B$4=\"base\",'Assumptions'!$D$52,'Assumptions'!$D$71))","Operating!D19":"=IF(Assumptions!$B$4=\"bear\",'Assumptions'!$D$34,IF(Assumptions!$B$4=\"base\",'Assumptions'!$D$53,'Assumptions'!$D$72))","Operating!D20":"=IF(Assumptions!$B$4=\"bear\",'Assumptions'!$D$35,IF(Assumptions!$B$4=\"base\",'Assumptions'!$D$54,'Assumptions'!$D$73))","Operating!D23":"='Operating'!$D$10*'Operating'!$D$11*'Operating'!$D$12","Operating!D24":"='Operating'!$D$10*'Operating'!$D$13","Operating!D25":"='Operating'!$D$23*'Operating'!$D$14","Operating!D26":"='Operating'!$D$23-'Operating'!$D$24-'Operating'!$D$25-'Operating'!$D$16","Operating!D27":"=MAX(0,'Operating'!$D$26)*'Operating'!$D$15","Operating!D28":"='Operating'!$D$26-'Operating'!$D$27","Operating!D29":"='Operating'!$D$28+'Operating'!$D$16-'Operating'!$D$
