Workbook

Sheet Summary
A1: ASX:MLX / Summary
A4: Illustrative scenarios | Review assumptions before using these values
A7: Active scenario | B7: =Assumptions!B4 -> base
A8: Model value per share (AUD) | B8: =Valuation!$B$11 -> 0.76474871
A9: Equity value (AUD) | B9: =Valuation!$B$9 -> 6.7786755e+08
A10: Minimum cash (AUD) | B10: =Valuation!$B$12 -> 373998000
A12: Start with the investment report for the full story. Choose a scenario on Assumptions, then explore its cash flows, valuation and sensitivities here.
A16: These figures illustrate the supplied assumptions, not a predicted share price. The cash chart excludes financing and dividends. Readme explains the limitations and evidence still needed.

Sheet Assumptions
A1: ASX:MLX / Assumptions
A4: Active scenario | B4: base | C4: Blue = editable inputs • Green = cross-sheet links • Black = calculations
A7: Cash | B7: 373998000 | C7: AUD
A8: Debt | B8: 1100000 | C8: AUD
A9: Other Assets | B9: 0 | C9: AUD
A10: Diluted Shares | B10: 886392538 | C10: shares
A11: Reference Price | B11: 2.15 | C11: AUD/share
A12: Valuation Date | B12: 2026-09-20 | C12: YYYY-MM-DD
A13: Quote Date | B13: 2026-09-18 | C13: YYYY-MM-DD
A15: Enter dates as YYYY-MM-DD text. Blank quote and reference price mean no market comparison. Preserve the declared ownership basis; attributable inputs require ownership = 100%.
A19: BEAR / whole_operation
A20: Discount Rate | B20: 0.12
A21: Ownership | B21: 0.5
A22: Residual Value | B22: 0
A23: Explicit forecast periods | B23: 3
C24: 2027 | D24: 2028 | E24: 2029 | F24: 2030 | G24: 2031 | H24: 2032 | I24: 2033
A25: Production proxy (not payable sales) | B25: tonnes | C25: 8986.1885 | D25: 10158.3 | E25: 10158.3 | F25: 0 | G25: 0 | H25: 0 | I25: 0
A26: Price | B26: AUD/tonne | C26: 51008 | D26: 51008 | E26: 51008 | F26: 0 | G26: 0 | H26: 0 | I26: 0
A27: Fx | B27: AUD/AUD | C27: 1 | D27: 1 | E27: 1 | F27: 0 | G27: 0 | H27: 0 | I27: 0
A28: Unit Cost | B28: AUD/tonne | C28: 34118.557 | D28: 30181.8 | E28: 30181.8 | F28: 0 | G28: 0 | H28: 0 | I28: 0
A29: Royalty Rate | B29: fraction | C29: 0 | D29: 0 | E29: 0 | F29: 0 | G29: 0 | H29: 0 | I29: 0
A30: Tax Rate | B30: fraction | C30: 0.3 | D30: 0.3 | E30: 0.3 | F30: 0 | G30: 0 | H30: 0 | I30: 0
A31: Depreciation | B31: AUD | C31: 0 | D31: 0 | E31: 0 | F31: 0 | G31: 0 | H31: 0 | I31: 0
A32: Capex | B32: AUD | C32: 93600000 | D32: 93600000 | E32: 93600000 | F32: 0 | G32: 0 | H32: 0 | I32: 0
A33: Working Capital Change | B33: AUD | C33: 0 | D33: 0 | E33: 0 | F33: 0 | G33: 0 | H33: 0 | I33: 0
A34: Closure | B34: AUD | C34: 0 | D34: 0 | E34: 100000000 | F34: 0 | G34: 0 | H34: 0 | I34: 0
A35: Corporate Cost | B35: AUD | C35: 2240000 | D35: 2240000 | E35: 2240000 | F35: 0 | G35: 0 | H35: 0 | I35: 0
A38: BASE / whole_operation
A39: Discount Rate | B39: 0.1
A40: Ownership | B40: 0.5
A41: Residual Value | B41: 0
A42: Explicit forecast periods | B42: 5
C43: 2027 | D43: 2028 | E43: 2029 | F43: 2030 | G43: 2031 | H43: 2032 | I43: 2033
A44: Production proxy (not payable sales) | B44: tonnes | C44: 10201.712 | D44: 11287 | E44: 11287 | F44: 11287 | G44: 11287 | H44: 0 | I44: 0
A45: Price | B45: AUD/tonne | C45: 63760 | D45: 63760 | E45: 63760 | F45: 63760 | G45: 63760 | H45: 0 | I45: 0
A46: Fx | B46: AUD/AUD | C46: 1 | D46: 1 | E46: 1 | F46: 1 | G46: 1 | H46: 0 | I46: 0
A47: Unit Cost | B47: AUD/tonne | C47: 30356.936 | D47: 27438 | E47: 27438 | F47: 27438 | G47: 27438 | H47: 0 | I47: 0
A48: Royalty Rate | B48: fraction | C48: 0 | D48: 0 | E48: 0 | F48: 0 | G48: 0 | H48: 0 | I48: 0
A49: Tax Rate | B49: fraction | C49: 0.3 | D49: 0.3 | E49: 0.3 | F49: 0.3 | G49: 0.3 | H49: 0 | I49: 0
A50: Depreciation | B50: AUD | C50: 0 | D50: 0 | E50: 0 | F50: 0 | G50: 0 | H50: 0 | I50: 0
...

Sheet Historical
A1: ASX:MLX / Historical
A4: Source-linked reported facts. Historical coverage may be incomplete; no integrated statements are inferred.
A6: Metric | B6: Period | C6: Value | D6: Unit | E6: Currency | F6: Basis / ownership | G6: Published | H6: Source | I6: Page
A7: Cash and cash equivalents | B7: 2025-12-31 | C7: 293606000 | D7: AUD | E7: AUD | F7: reported / consolidated | G7: 2026-03-25 | H7: Open source report | I7: 25
A8: Current interest bearing liabilities | B8: 2025-12-31 | C8: 2849000 | D8: AUD | E8: AUD | F8: reported / consolidated | G8: 2026-03-25 | H8: Open source report | I8: 25
A9: Noncurrent interest bearing liabilities | B9: 2025-12-31 | C9: 436000 | D9: AUD | E9: AUD | F9: reported / consolidated | G9: 2026-03-25 | H9: Open source report | I9: 25
A10: Issued ordinary shares | B10: 2025-12-31 | C10: 886392538 | D10: shares | F10: reported comparative; corrects earlier transcription / consolidated | G10: 2026-08-28 | H10: Open source report | I10: 27
A11: Rehabilitation provision present value | B11: 2025-12-31 | C11: 33035000 | D11: AUD | E11: AUD | F11: reported / consolidated | G11: 2026-03-25 | H11: Open source report | I11: 60
A12: Net operating cash flow | B12: FY2025 | C12: 128323000 | D12: AUD | E12: AUD | F12: reported / consolidated | G12: 2026-03-25 | H12: Open source report | I12: 26
A13: Cash paid property plant equipment | B13: FY2025 | C13: 13747000 | D13: AUD | E13: AUD | F13: reported / consolidated | G13: 2026-03-25 | H13: Open source report | I13: 26
A14: Cash paid mine properties development | B14: FY2025 | C14: 22211000 | D14: AUD | E14: AUD | F14: reported / consolidated | G14: 2026-03-25 | H14: Open source report | I14: 26
A15: Tin in concentrate produced | B15: FY2025 | C15: 10748 | D15: tonnes_tin | F15: reported / whole_operation | G15: 2026-03-25 | H15: Open source report | I15: 9
A16: Ownership interest | B16: 2026-Q2 | C16: 0.5 | D16: fraction | F16: reported / whole_operation | G16: 2026-07-27 | H16: Open source report | I16: 2
A17: Tin in concentrate produced | B17: 2026-Q2 | C17: 2809 | D17: tonnes_tin | F17: reported / whole_operation | G17: 2026-07-27 | H17: Open source report | I17: 2
A18: Tin in concentrate produced | B18: TTM-ended-2026-06-30 | C18: 11287 | D18: tonnes_tin | F18: reported / whole_operation | G18: 2026-07-27 | H18: Open source report | I18: 2
A19: Imputed tin price | B19: 2026-Q2 | C19: 73834 | D19: AUD_per_tonne_tin | E19: AUD | F19: reported / whole_operation | G19: 2026-07-27 | H19: Open source report | I19: 2
A20: Imputed tin price | B20: TTM-ended-2026-06-30 | C20: 63760 | D20: AUD_per_tonne_tin | E20: AUD | F20: reported / whole_operation | G20: 2026-07-27 | H20: Open source report | I20: 2
A21: C1 cash production cost | B21: 2026-Q2 | C21: 20251 | D21: AUD_per_tonne_tin | E21: AUD | F21: reported / whole_operation | G21: 2026-07-27 | H21: Open source report | I21: 2
A22: C1 cash production cost | B22: TTM-ended-2026-06-30 | C22: 19349 | D22: AUD_per_tonne_tin | E22: AUD | F22: reported / whole_operation | G22: 2026-07-27 | H22: Open source report | I22: 2
A23: Imputed sales and marketing cost | B23: 2026-Q2 | C23: 8758 | D23: AUD_per_tonne_tin | E23: AUD | F23: reported / whole_operation | G23: 2026-07-27 | H23: Open source report | I23: 2
A24: All in sustaining cost | B24: 2026-Q2 | C24: 34865 | D24: AUD_per_tonne_tin | E24: AUD | F24: reported / whole_operation | G24: 2026-07-27 | H24: Open source report | I24: 2
A25: Capital expenditure | B25: 2026-Q2 | C25: 23400000 | D25: AUD | E25: AUD | F25: reported / whole_operation | G25: 2026-07-27 | H25: Open source report | I25: 3
A26: Sustaining capital expenditure | B26: 2026-Q2 | C26: 16450000 | D26: AUD | E26: AUD | F26: reported / whole_operation | G26: 2026-07-27 | H26: Open source report | I26: 3
A27: Project capital expenditure | B27: 2026-Q2 | C27: 6950000 | D27: AUD | E27: AUD | F27: reported / whole_operation | G27: 2026-07-27 | H27: Open source report | I27: 3
A28: Cash and cash equivalents | B28: 2026-06-30 | C28: 373998000 | D28: AUD | E28: AUD | F28: reported / consolidated | G28: 2026-08-28 | H28: Open source report | I28: 16
A29: Corporate costs | B29: 2026-Q2 | C29: 560000 | D29: AUD | E29: AUD | F29: reported / consolidated | G29: 2026-07-27 | H29: Open source report | I29: 8
A30: Revenue | B30: FY2025 | C30: 284999000 | D30: AUD | E30: AUD | F30: reported / consolidated | G30: 2026-03-25 | H30: Open source report | I30: 24
... A113: Capital expenditure commitments | B113: 2026-06-30 | C113: 16790000 | D113: AUD | E113: AUD | F113: reported / consolidated | G113: 2026-08-28 | H113: Open source report | I113: 27
A114: Issued ordinary shares | B114: 2026-06-30 | C114: 886392538 | D114: shares | F114: reported / consolidated | G114: 2026-08-28 | H114: Open source report | I114: 27
A115: Tin in concentrate produced | B115: H1 2025 | C115: 5156 | D115: tonnes_tin | F115: reported / 100% whole operation | G115: 2026-08-28 | H115: Open source report | I115: 7
A116: Tin in concentrate produced | B116: H1 2026 | C116: 5696 | D116: tonnes_tin | F116: reported / 100% whole operation | G116: 2026-08-28 | H116: Open source report | I116: 7
A117: Revenue | B117: FY2023 | C117: 153781000 | D117: AUD | E117: AUD | F117: reported / consolidated | G117: 2024-04-09 | H117: Open source report | I117: 22
A118: Cost of sales | B118: FY2023 | C118: 105155000 | D118: AUD | E118: AUD | F118: reported / consolidated | G118: 2024-04-09 | H118: Open source report | I118: 22
A119: Gross profit | B119: FY2023 | C119: 48626000 | D119: AUD | E119: AUD | F119: reported / consolidated | G119: 2024-04-09 | H119: Open source report | I119: 22
A120: Net income | B120: FY2023 | C120: 14585000 | D120: AUD | E120: AUD | F120: reported / consolidated | G120: 2024-04-09 | H120: Open source report | I120: 22
A121: Net operating cash flow | B121: FY2023 | C121: 64860000 | D121: AUD | E121: AUD | F121: reported / consolidated | G121: 2024-04-09 | H121: Open source report | I121: 24
A122: Cash paid property plant equipment | B122: FY2023 | C122: 13035000 | D122: AUD | E122: AUD | F122: reported / consolidated | G122: 2024-04-09 | H122: Open source report | I122: 24
A123: Cash paid mine properties development | B123: FY2023 | C123: 21891000 | D123: AUD | E123: AUD | F123: reported / consolidated | G123: 2024-04-09 | H123: Open source report | I123: 24
A124: Net investing cash flow | B124: FY2023 | C124: -32650000 | D124: AUD | E124: AUD | F124: reported / consolidated | G124: 2024-04-09 | H124: Open source report | I124: 24
A125: Net financing cash flow | B125: FY2023 | C125: -3097000 | D125: AUD | E125: AUD | F125: reported / consolidated | G125: 2024-04-09 | H125: Open source report | I125: 24
...

Sheet Analysis
A1: ASX:MLX / Analysis
A4: Reported history | H1 2025 versus H1 2026 | AUD millions
A6: Reported measure | B6: H1 2025 | C6: H1 2026 | D6: Change
A7: Revenue | B7: =Historical!C80/1000000 -> 147.539 | C7: =Historical!C81/1000000 -> 204.729 | D7: =C7-B7 -> 57.19
A8: Gross profit | B8: =Historical!C84/1000000 -> 63.706 | C8: =Historical!C85/1000000 -> 123.342 | D8: =C8-B8 -> 59.636
A9: Profit before tax | B9: =Historical!C86/1000000 -> 73.176 | C9: =Historical!C87/1000000 -> 128.601 | D9: =C9-B9 -> 55.425
A10: Income tax expense | B10: =Historical!C88/1000000 -> 20.228 | C10: =Historical!C89/1000000 -> 24.696 | D10: =C10-B10 -> 4.468
A11: Net profit | B11: =Historical!C90/1000000 -> 52.948 | C11: =Historical!C91/1000000 -> 103.905 | D11: =C11-B11 -> 50.957
A12: Operating cash flow | B12: =Historical!C92/1000000 -> 64.274 | C12: =Historical!C93/1000000 -> 126.515 | D12: =C12-B12 -> 62.241
A13: Equipment spending | B13: =Historical!C94/1000000 -> 2.912 | C13: =Historical!C95/1000000 -> 7.879 | D13: =C13-B13 -> 4.967
A14: Mine-development spending | B14: =Historical!C96/1000000 -> 13.862 | C14: =Historical!C97/1000000 -> 12.45 | D14: =C14-B14 -> -1.412
A15: Investing cash flow | B15: =Historical!C98/1000000 -> -51.758 | C15: =Historical!C99/1000000 -> -43.937 | D15: =C15-B15 -> 7.821
A16: Financing cash flow | B16: =Historical!C100/1000000 -> -2.282 | C16: =Historical!C101/1000000 -> -2.186 | D16: =C16-B16 -> 0.096
A17: Opening cash | B17: =Historical!C104/1000000 -> 220.644 | C17: =Historical!C105/1000000 -> 293.606 | D17: =C17-B17 -> 72.962
A19: Gross margin | B19: =IF(B7>0,B8/B7,"N/A") -> 0.43179092 | C19: =IF(C7>0,C8/C7,"N/A") -> 0.60246472
A20: Cash flow / net profit | B20: =IF(B11>0,B12/B11,"N/A") -> 1.213908 | C20: =IF(C11>0,C12/C11,"N/A") -> 1.2176026
A21: Operating cash less mine/equipment spend | B21: =B12-B13-B14 -> 47.5 | C21: =C12-C13-C14 -> 106.186
A22: Closing cash (reconciled) | B22: =B17+B12+B15+B16 -> 230.878 | C22: =C17+C12+C15+C16 -> 373.998
A24: Cash conversion is a diagnostic, not an earnings-quality score. Cash after equipment and mine spending still precedes other investing uses and financing. Periods and ownership match; historical values are not forecasts.
A27: WHY PROFIT CHANGED | accounting bridge, not a price/volume attribution
A29: Prior net profit | B29: =B11 -> 52.948
A30: Gross profit change | B30: =C8-B8 -> 59.636
A31: Other pre-tax changes, net | B31: =(C9-C8)-(B9-B8) -> -4.211
A32: Tax expense change | B32: =B10-C10 -> -4.468
A33: Current net profit | B33: =C11 -> 103.905
A35: Profit bridge residual (must be zero) | B35: =SUM(B29:B32)-B33 -> 0
A37: WHERE CASH WENT | current period
A39: Opening cash | B39: =C17 -> 293.606
A40: Operating cash flow | B40: =C12 -> 126.515
A41: Equipment and mine development | B41: =-C13-C14 -> -20.329
A42: Other investing cash flow, net | B42: =C15+C13+C14 -> -23.608
A43: Financing cash flow | B43: =C16 -> -2.186
A44: Closing cash | B44: =C22 -> 373.998
A46: Cash bridge residual (must be zero) | B46: =SUM(B39:B43)-B44 -> 0
A49: Read the report for tax effects, collection timing and capital-allocation judgments. Other pre-tax changes are an explicitly aggregated residual; their components need source review. The cash bridge is not a reconciliation from profit to operating cash.

Sheet Operating
A1: ASX:MLX / Operating
A4: Discount Rate | B4: =IF(Assumptions!$B$4="bear",Assumptions!$B$20,IF(Assumptions!$B$4="base",Assumptions!$B$39,Assumptions!$B$58)) -> 0.1
A5: Ownership | B5: =IF(Assumptions!$B$4="bear",Assumptions!$B$21,IF(Assumptions!$B$4="base",Assumptions!$B$40,Assumptions!$B$59)) -> 0.5
A6: Residual Value | B6: =IF(Assumptions!$B$4="bear",Assumptions!$B$22,IF(Assumptions!$B$4="base",Assumptions!$B$41,Assumptions!$B$60)) -> 0
A7: Horizon | B7: =IF(Assumptions!$B$4="bear",Assumptions!$B$23,IF(Assumptions!$B$4="base",Assumptions!$B$42,Assumptions!$B$61)) -> 5
A8: Volume basis | B8: =IF(Assumptions!$B$4="bear","imputed_production",IF(Assumptions!$B$4="base","imputed_production","imputed_production")) -> imputed_production
A9: Annual end-of-period forecast | C9: =YEAR(DATEVALUE(Assumptions!$B$12))+1 -> 2027 | D9: =YEAR(DATEVALUE(Assumptions!$B$12))+2 -> 2028 | E9: =YEAR(DATEVALUE(Assumptions!$B$12))+3 -> 2029 | F9: =YEAR(DATEVALUE(Assumptions!$B$12))+4 -> 2030 | G9: =YEAR(DATEVALUE(Assumptions!$B$12))+5 -> 2031 | H9: =YEAR(DATEVALUE(Assumptions!$B$12))+6 -> 2032 | I9: =YEAR(DATEVALUE(Assumptions!$B$12))+7 -> 2033
A10: Volume (see case basis) | B10: tonnes | C10: =IF(Assumptions!$B$4="bear",Assumptions!$C$25,IF(Assumptions!$B$4="base",Assumptions!$C$44,Assumptions!$C$63)) -> 10201.712 | D10: =IF(Assumptions!$B$4="bear",Assumptions!$D$25,IF(Assumptions!$B$4="base",Assumptions!$D$44,Assumptions!$D$63)) -> 11287 | E10: =IF(Assumptions!$B$4="bear",Assumptions!$E$25,IF(Assumptions!$B$4="base",Assumptions!$E$44,Assumptions!$E$63)) -> 11287 | F10: =IF(Assumptions!$B$4="bear",Assumptions!$F$25,IF(Assumptions!$B$4="base",Assumptions!$F$44,Assumptions!$F$63)) -> 11287 | G10: =IF(Assumptions!$B$4="bear",Assumptions!$G$25,IF(Assumptions!$B$4="base",Assumptions!$G$44,Assumptions!$G$63)) -> 11287 | H10: =IF(Assumptions!$B$4="bear",Assumptions!$H$25,IF(Assumptions!$B$4="base",Assumptions!$H$44,Assumptions!$H$63)) -> 0 | I10: =IF(Assumptions!$B$4="bear",Assumptions!$I$25,IF(Assumptions!$B$4="base",Assumptions!$I$44,Assumptions!$I$63)) -> 0
A11: Price | B11: see case input units | C11: =IF(Assumptions!$B$4="bear",Assumptions!$C$26,IF(Assumptions!$B$4="base",Assumptions!$C$45,Assumptions!$C$64)) -> 63760 | D11: =IF(Assumptions!$B$4="bear",Assumptions!$D$26,IF(Assumptions!$B$4="base",Assumptions!$D$45,Assumptions!$D$64)) -> 63760 | E11: =IF(Assumptions!$B$4="bear",Assumptions!$E$26,IF(Assumptions!$B$4="base",Assumptions!$E$45,Assumptions!$E$64)) -> 63760 | F11: =IF(Assumptions!$B$4="bear",Assumptions!$F$26,IF(Assumptions!$B$4="base",Assumptions!$F$45,Assumptions!$F$64)) -> 63760 | G11: =IF(Assumptions!$B$4="bear",Assumptions!$G$26,IF(Assumptions!$B$4="base",Assumptions!$G$45,Assumptions!$G$64)) -> 63760 | H11: =IF(Assumptions!$B$4="bear",Assumptions!$H$26,IF(Assumptions!$B$4="base",Assumptions!$H$45,Assumptions!$H$64)) -> 0 | I11: =IF(Assumptions!$B$4="bear",Assumptions!$I$26,IF(Assumptions!$B$4="base",Assumptions!$I$45,Assumptions!$I$64)) -> 0
A12: Fx | B12: see case input units | C12: =IF(Assumptions!$B$4="bear",Assumptions!$C$27,IF(Assumptions!$B$4="base",Assumptions!$C$46,Assumptions!$C$65)) -> 1 | D12: =IF(Assumptions!$B$4="bear",Assumptions!$D$27,IF(Assumptions!$B$4="base",Assumptions!$D$46,Assumptions!$D$65)) -> 1 | E12: =IF(Assumptions!$B$4="bear",Assumptions!$E$27,IF(Assumptions!$B$4="base",Assumptions!$E$46,Assumptions!$E$65)) -> 1 | F12: =IF(Assumptions!$B$4="bear",Assumptions!$F$27,IF(Assumptions!$B$4="base",Assumptions!$F$46,Assumptions!$F$65)) -> 1 | G12: =IF(Assumptions!$B$4="bear",Assumptions!$G$27,IF(Assumptions!$B$4="base",Assumptions!$G$46,Assumptions!$G$65)) -> 1 | H12: =IF(Assumptions!$B$4="bear",Assumptions!$H$27,IF(Assumptions!$B$4="base",Assumptions!$H$46,Assumptions!$H$65)) -> 0 | I12: =IF(Assumptions!$B$4="bear",Assumptions!$I$27,IF(Assumptions!$B$4="base",Assumptions!$I$46,Assumptions!$I$65)) -> 0
A13: Unit Cost | B13: AUD/tonne | C13: =IF(Assumptions!$B$4="bear",Assumptions!$C$28,IF(Assumptions!$B$4="base",Assumptions!$C$47,Assumptions!$C$66)) -> 30356.936 | D13: =IF(Assumptions!$B$4="bear",Assumptions!$D$28,IF(Assumptions!$B$4="base",Assumptions!$D$47,Assumptions!$D$66)) -> 27438 | E13: =IF(Assumptions!$B$4="bear",Assumptions!$E$28,IF(Assumptions!$B$4="base",Assumptions!$E$47,Assumptions!$E$66)) -> 27438 | F13: =IF(Assumptions!$B$4="bear",Assumptions!$F$28,IF(Assumptions!$B$4="base",Assumptions!$F$47,Assumptions!$F$66)) -> 27438 | G13: =IF(Assumptions!$B$4="bear",Assumptions!$G$28,IF(Assumptions!$B$4="base",Assumptions!$G$47,Assumptions!$G$66)) -> 27438 | H13: =IF(Assumptions!$B$4="bear",Assumptions!$H$28,IF(Assumptions!$B$4="base",Assumptions!$H$47,Assumptions!$H$66)) -> 0 | I13: =IF(Assumptions!$B$4="bear",Assumptions!$I$28,IF(Assumptions!$B$4="base",Assumptions!$I$47,Assumptions!$I$66)) -> 0
A14: Royalty Rate | B14: fraction | C14: =IF(Assumptions!$B$4="bear",Assumptions!$C$29,IF(Assumptions!$B$4="base",Assumptions!$C$48,Assumptions!$C$67)) -> 0 | D14: =IF(Assumptions!$B$4="bear",Assumptions!$D$29,IF(Assumptions!$B$4="base",Assumptions!$D$48,Assumptions!$D$67)) -> 0 | E14: =IF(Assumptions!$B$4="bear",Assumptions!$E$29,IF(Assumptions!$B$4="base",Assumptions!$E$48,Assumptions!$E$67)) -> 0 | F14: =IF(Assumptions!$B$4="bear",Assumptions!$F$29,IF(Assumptions!$B$4="base",Assumptions!$F$48,Assumptions!$F$67)) -> 0 | G14: =IF(Assumptions!$B$4="bear",Assumptions!$G$29,IF(Assumptions!$B$4="base",Assumptions!$G$48,Assumptions!$G$67)) -> 0 | H14: =IF(Assumptions!$B$4="bear",Assumptions!$H$29,IF(Assumptions!$B$4="base",Assumptions!$H$48,Assumptions!$H$67)) -> 0 | I14: =IF(Assumptions!$B$4="bear",Assumptions!$I$29,IF(Assumptions!$B$4="base",Assumptions!$I$48,Assumptions!$I$67)) -> 0
A15: Tax Rate | B15: fraction | C15: =IF(Assumptions!$B$4="bear",Assumptions!$C$30,IF(Assumptions!$B$4="base",Assumptions!$C$49,Assumptions!$C$68)) -> 0.3 | D15: =IF(Assumptions!$B$4="bear",Assumptions!$D$30,IF(Assumptions!$B$4="base",Assumptions!$D$49,Assumptions!$D$68)) -> 0.3 | E15: =IF(Assumptions!$B$4="bear",Assumptions!$E$30,IF(Assumptions!$B$4="base",Assumptions!$E$49,Assumptions!$E$68)) -> 0.3 | F15: =IF(Assumptions!$B$4="bear",Assumptions!$F$30,IF(Assumptions!$B$4="base",Assumptions!$F$49,Assumptions!$F$68)) -> 0.3 | G15: =IF(Assumptions!$B$4="bear",Assumptions!$G$30,IF(Assumptions!$B$4="base",Assumptions!$G$49,Assumptions!$G$68)) -> 0.3 | H15: =IF(Assumptions!$B$4="bear",Assumptions!$H$30,IF(Assumptions!$B$4="base",Assumptions!$H$49,Assumptions!$H$68)) -> 0 | I15: =IF(Assumptions!$B$4="bear",Assumptions!$I$30,IF(Assumptions!$B$4="base",Assumptions!$I$49,Assumptions!$I$68)) -> 0
A16: Depreciation | B16: AUD | C16: =IF(Assumptions!$B$4="bear",Assumptions!$C$31,IF(Assumptions!$B$4="base",Assumptions!$C$50,Assumptions!$C$69)) -> 0 | D16: =IF(Assumptions!$B$4="bear",Assumptions!$D$31,IF(Assumptions!$B$4="base",Assumptions!$D$50,Assumptions!$D$69)) -> 0 | E16: =IF(Assumptions!$B$4="bear",Assumptions!$E$31,IF(Assumptions!$B$4="base",Assumptions!$E$50,Assumptions!$E$69)) -> 0 | F16: =IF(Assumptions!$B$4="bear",Assumptions!$F$31,IF(Assumptions!$B$4="base",Assumptions!$F$50,Assumptions!$F$69)) -> 0 | G16: =IF(Assumptions!$B$4="bear",Assumptions!$G$31,IF(Assumptions!$B$4="base",Assumptions!$G$50,Assumptions!$G$69)) -> 0 | H16: =IF(Assumptions!$B$4="bear",Assumptions!$H$31,IF(Assumptions!$B$4="base",Assumptions!$H$50,Assumptions!$H$69)) -> 0 | I16: =IF(Assumptions!$B$4="bear",Assumptions!$I$31,IF(Assumptions!$B$4="base",Assumptions!$I$50,Assumptions!$I$69)) -> 0
A17: Capex | B17: AUD | C17: =IF(Assumptions!$B$4="bear",Assumptions!$C$32,IF(Assumptions!$B$4="base",Assumptions!$C$51,Assumptions!$C$70)) -> 93600000 | D17: =IF(Assumptions!$B$4="bear",Assumptions!$D$32,IF(Assumptions!$B$4="base",Assumptions!$D$51,Assumptions!$D$70)) -> 93600000 | E17: =IF(Assumptions!$B$4="bear",Assumptions!$E$32,IF(Assumptions!$B$4="base",Assumptions!$E$51,Assumptions!$E$70)) -> 93600000 | F17: =IF(Assumptions!$B$4="bear",Assumptions!$F$32,IF(Assumptions!$B$4="base",Assumptions!$F$51,Assumptions!$F$70)) -> 93600000 | G17: =IF(Assumptions!$B$4="bear",Assumptions!$G$32,IF(Assumptions!$B$4="base",Assumptions!$G$51,Assumptions!$G$70)) -> 93600000 | H17: =IF(Assumptions!$B$4="bear",Assumptions!$H$32,IF(Assumptions!$B$4="base",Assumptions!$H$51,Assumptions!$H$70)) -> 0 | I17: =IF(Assumptions!$B$4="bear",Assumptions!$I$32,IF(Assumptions!$B$4="base",Assumptions!$I$51,Assumptions!$I$70)) -> 0
A18: Working Capital Change | B18: AUD | C18: =IF(Assumptions!$B$4="bear",Assumptions!$C$33,IF(Assumptions!$B$4="base",Assumptions!$C$52,Assumptions!$C$71)) -> 0 | D18: =IF(Assumptions!$B$4="bear",Assumptions!$D$33,IF(Assumptions!$B$4="base",Assumptions!$D$52,Assumptions!$D$71)) -> 0 | E18: =IF(Assumptions!$B$4="bear",Assumptions!$E$33,IF(Assumptions!$B$4="base",Assumptions!$E$52,Assumptions!$E$71)) -> 0 | F18: =IF(Assumptions!$B$4="bear",Assumptions!$F$33,IF(Assumptions!$B$4="base",Assumptions!$F$52,Assumptions!$F$71)) -> 0 | G18: =IF(Assumptions!$B$4="bear",Assumptions!$G$33,IF(Assumptions!$B$4="base",Assumptions!$G$52,Assumptions!$G$71)) -> 0 | H18: =IF(Assumptions!$B$4="bear",Assumptions!$H$33,IF(Assumptions!$B$4="base",Assumptions!$H$52,Assumptions!$H$71)) -> 0 | I18: =IF(Assumptions!$B$4="bear",Assumptions!$I$33,IF(Assumptions!$B$4="base",Assumptions!$I$52,Assumptions!$I$71)) -> 0
A19: Closure | B19: AUD | C19: =IF(Assumptions!$B$4="bear",Assumptions!$C$34,IF(Assumptions!$B$4="base",Assumptions!$C$53,Assumptions!$C$72)) -> 0 | D19: =IF(Assumptions!$B$4="bear",Assumptions!$D$34,IF(Assumptions!$B$4="base",Assumptions!$D$53,Assumptions!$D$72)) -> 0 | E19: =IF(Assumptions!$B$4="bear",Assumptions!$E$34,IF(Assumptions!$B$4="base",Assumptions!$E$53,Assumptions!$E$72)) -> 0 | F19: =IF(Assumptions!$B$4="bear",Assumptions!$F$34,IF(Assumptions!$B$4="base",Assumptions!$F$53,Assumptions!$F$72)) -> 0 | G19: =IF(Assumptions!$B$4="bear",Assumptions!$G$34,IF(Assumptions!$B$4="base",Assumptions!$G$53,Assumptions!$G$72)) -> 100000000 | H19: =IF(Assumptions!$B$4="bear",Assumptions!$H$34,IF(Assumptions!$B$4="base",Assumptions!$H$53,Assumptions!$H$72)) -> 0 | I19: =IF(Assumptions!$B$4="bear",Assumptions!$I$34,IF(Assumptions!$B$4="base",Assumptions!$I$53,Assumptions!$I$72)) -> 0
A20: Corporate Cost | B20: AUD | C20: =IF(Assumptions!$B$4="bear",Assumptions!$C$35,IF(Assumptions!$B$4="base",Assumptions!$C$54,Assumptions!$C$73)) -> 2240000 | D20: =IF(Assumptions!$B$4="bear",Assumptions!$D$35,IF(Assumptions!$B$4="base",Assumptions!$D$54,Assumptions!$D$73)) -> 2240000 | E20: =IF(Assumptions!$B$4="bear",Assumptions!$E$35,IF(Assumptions!$B$4="base",Assumptions!$E$54,Assumptions!$E$73)) -> 2240000 | F20: =IF(Assumptions!$B$4="bear",Assumptions!$F$35,IF(Assumptions!$B$4="base",Assumptions!$F$54,Assumptions!$F$73)) -> 2240000 | G20: =IF(Assumptions!$B$4="bear",Assumptions!$G$35,IF(Assumptions!$B$4="base",Assumptions!$G$54,Assumptions!$G$73)) -> 2240000 | H20: =IF(Assumptions!$B$4="bear",Assumptions!$H$35,IF(Assumptions!$B$4="base",Assumptions!$H$54,Assumptions!$H$73)) -> 0 | I20: =IF(Assumptions!$B$4="bear",Assumptions!$I$35,IF(Assumptions!$B$4="base",Assumptions!$I$54,Assumptions!$I$73)) -> 0
A23: Revenue | B23: AUD | C23: =Operating!$C$10*Operating!$C$11*Operating!$C$12 -> 6.5046113e+08 | D23: =Operating!$D$10*Operating!$D$11*Operating!$D$12 -> 719659120 | E23: =Operating!$E$10*Operating!$E$11*Operating!$E$12 -> 719659120 | F23: =Operating!$F$10*Operating!$F$11*Operating!$F$12 -> 719659120 | G23: =Operating!$G$10*Operating!$G$11*Operating!$G$12 -> 719659120 | H23: =Operating!$H$10*Operating!$H$11*Operating!$H$12 -> 0 | I23: =Operating!$I$10*Operating!$I$11*Operating!$I$12 -> 0
A24: Operating Cost | B24: AUD | C24: =Operating!$C$10*Operating!$C$13 -> 309692706 | D24: =Operating!$D$10*Operating!$D$13 -> 309692706 | E24: =Operating!$E$10*Operating!$E$13 -> 309692706 | F24: =Operating!$F$10*Operating!$F$13 -> 309692706 | G24: =Operating!$G$10*Operating!$G$13 -> 309692706 | H24: =Operating!$H$10*Operating!$H$13 -> 0 | I24: =Operating!$I$10*Operating!$I$13 -> 0
A25: Royalties | B25: AUD | C25: =Operating!$C$23*Operating!$C$14 -> 0 | D25: =Operating!$D$23*Operating!$D$14 -> 0 | E25: =Operating!$E$23*Operating!$E$14 -> 0 | F25: =Operating!$F$23*Operating!$F$14 -> 0 | G25: =Operating!$G$23*Operating!$G$14 -> 0 | H25: =Operating!$H$23*Operating!$H$14 -> 0 | I25: =Operating!$I$23*Operating!$I$14 -> 0
A26: Ebit | B26: AUD | C26: =Operating!$C$23-Operating!$C$24-Operating!$C$25-Operating!$C$16 -> 3.4076842e+08 | D26: =Operating!$D$23-Operating!$D$24-Operating!$D$25-Operating!$D$16 -> 409966414 | E26: =Operating!$E$23-Operating!$E$24-Operating!$E$25-Operating!$E$16 -> 409966414 | F26: =Operating!$F$23-Operating!$F$24-Operating!$F$25-Operating!$F$16 -> 409966414 | G26: =Operating!$G$23-Operating!$G$24-Operating!$G$25-Operating!$G$16 -> 409966414 | H26: =Operating!$H$23-Operating!$H$24-Operating!$H$25-Operating!$H$16 -> 0 | I26: =Operating!$I$23-Operating!$I$24-Operating!$I$25-Operating!$I$16 -> 0
A27: Tax | B27: AUD | C27: =MAX(0,Operating!$C$26)*Operating!$C$15 -> 1.0223053e+08 | D27: =MAX(0,Operating!$D$26)*Operating!$D$15 -> 1.2298992e+08 | E27: =MAX(0,Operating!$E$26)*Operating!$E$15 -> 1.2298992e+08 | F27: =MAX(0,Operating!$F$26)*Operating!$F$15 -> 1.2298992e+08 | G27: =MAX(0,Operating!$G$26)*Operating!$G$15 -> 1.2298992e+08 | H27: =MAX(0,Operating!$H$26)*Operating!$H$15 -> 0 | I27: =MAX(0,Operating!$I$26)*Operating!$I$15 -> 0
A28: Nopat | B28: AUD | C28: =Operating!$C$26-Operating!$C$27 -> 2.385379e+08 | D28: =Operating!$D$26-Operating!$D$27 -> 2.8697649e+08 | E28: =Operating!$E$26-Operating!$E$27 -> 2.8697649e+08 | F28: =Operating!$F$26-Operating!$F$27 -> 2.8697649e+08 | G28: =Operating!$G$26-Operating!$G$27 -> 2.8697649e+08 | H28: =Operating!$H$26-Operating!$H$27 -> 0 | I28: =Operating!$I$26-Operating!$I$27 -> 0
A29: Operating Fcf | B29: AUD | C29: =Operating!$C$28+Operating!$C$16-Operating!$C$17-Operating!$C$18-Operating!$C$19 -> 1.449379e+08 | D29: =Operating!$D$28+Operating!$D$16-Operating!$D$17-Operating!$D$18-Operating!$D$19 -> 1.9337649e+08 | E29: =Operating!$E$28+Operating!$E$16-Operating!$E$17-Operating!$E$18-Operating!$E$19 -> 1.9337649e+08 | F29: =Operating!$F$28+Operating!$F$16-Operating!$F$17-Operating!$F$18-Operating!$F$19 -> 1.9337649e+08 | G29: =Operating!$G$28+Operating!$G$16-Operating!$G$17-Operating!$G$18-Operating!$G$19 -> 93376490 | H29: =Operating!$H$28+Operating!$H$16-Operating!$H$17-Operating!$H$18-Operating!$H$19 -> 0 | I29: =Operating!$I$28+Operating!$I$16-Operating!$I$17-Operating!$I$18-Operating!$I$19 -> 0
A30: Fcf | B30: AUD | C30: =Operating!$C$29*Operating!$B$5-Operating!$C$20+IF(1=Operating!$B$7,Operating!$B$6,0) -> 70228948 | D30: =Operating!$D$29*Operating!$B$5-Operating!$D$20+IF(2=Operating!$B$7,Operating!$B$6,0) -> 94448245 | E30: =Operating!$E$29*Operating!$B$5-Operating!$E$20+IF(3=Operating!$B$7,Operating!$B$6,0) -> 94448245 | F30: =Operating!$F$29*Operating!$B$5-Operating!$F$20+IF(4=Operating!$B$7,Operating!$B$6,0) -> 94448245 | G30: =Operating!$G$29*Operating!$B$5-Operating!$G$20+IF(5=Operating!$B$7,Operating!$B$6,0) -> 44448245 | H30: =Operating!$H$29*Operating!$B$5-Operating!$H$20+IF(6=Operating!$B$7,Operating!$B$6,0) -> 0 | I30: =Operating!$I$29*Operating!$B$5-Operating!$I$20+IF(7=Operating!$B$7,Operating!$B$6,0) -> 0
A31: Present Value | B31: AUD | C31: =Operating!$C$30/(1+Operating!$B$4)^1 -> 63844498 | D31: =Operating!$D$30/(1+Operating!$B$4)^2 -> 78056401 | E31: =Operating!$E$30/(1+Operating!$B$4)^3 -> 70960364 | F31: =Operating!$F$30/(1+Operating!$B$4)^4 -> 64509422 | G31: =Operating!$G$30/(1+Operating!$B$4)^5 -> 27598863 | H31: =Operating!$H$30/(1+Operating!$B$4)^6 -> 0 | I31: =Operating!$I$30/(1+Operating!$B$4)^7 -> 0
A32: Illustrative Cash | B32: AUD | C32: =Assumptions!$B$7+Operating!$C$30 -> 4.4422695e+08 | D32: =Operating!$C$32+Operating!$D$30 -> 5.3867519e+08 | E32: =Operating!$D$32+Operating!$E$30 -> 6.3312344e+08 | F32: =Operating!$E$32+Operating!$F$30 -> 7.2757168e+08 | G32: =Operating!$F$32+Operating!$G$30 -> 7.7201993e+08 | H32: =Operating!$G$32+Operating!$H$30 -> 7.7201993e+08 | I32: =Operating!$H$32+Operating!$I$30 -> 7.7201993e+08
A34: Illustrative cash excludes financing, dividends and debt maturities. This is a finite cash-flow schedule, not an integrated three-statement forecast. No terminal perpetuity is assumed.

Sheet Valuation
A1: ASX:MLX / Valuation
A5: Enterprise Value | B5: =SUM(Operating!C31:I31) -> 3.0496955e+08 | C5: AUD
A6: Cash | B6: =Assumptions!$B$7 -> 373998000 | C6: AUD
A7: Other Assets | B7: =Assumptions!$B$9 -> 0 | C7: AUD
A8: Debt | B8: =Assumptions!$B$8 -> 1100000 | C8: AUD
A9: Equity Value | B9: =B5+B6+B7-B8 -> 6.7786755e+08 | C9: AUD
A10: Diluted Shares | B10: =Assumptions!$B$10 -> 886392538 | C10: shares
A11: Per Share | B11: =B9/B10 -> 0.76474871 | C11: AUD/share
A12: Minimum Illustrative Cash | B12: =MIN(Assumptions!$B$7,Operating!C32:I32) -> 373998000 | C12: AUD
A15: Reference price | B15: =IF(Assumptions!$B$11="","Unavailable",Assumptions!$B$11) -> 2.15
A16: Model / reference price − 1 | B16: =IF(AND(ISNUMBER(B15),B15>0),B11/B15-1,"Unavailable") -> -0.64430293
A19: This is a model output, not a price target or investment recommendation. Corporate costs and residual value are company-attributable; operating cash flows apply ownership once. Residual value is explicit, not a perpetuity.

Sheet Sensitivities
A1: ASX:MLX / Sensitivities
A4: Price multiplier × discount rate / AUD per share. All active-case forecast years recomputed, including positive-EBIT tax floor.
C7: =MAX(0,Operating!$B$4+(-0.02)) -> 0.08 | D7: =MAX(0,Operating!$B$4+(0)) -> 0.1 | E7: =MAX(0,Operating!$B$4+(0.02)) -> 0.12
B8: 0.8 | C8: =(SUM(C17:I17)+Assumptions!$B$7+Assumptions!$B$9-Assumptions!$B$8)/Assumptions!$B$10 -> 0.56058207 | D8: =(SUM(C18:I18)+Assumptions!$B$7+Assumptions!$B$9-Assumptions!$B$8)/Assumptions!$B$10 -> 0.55427571 | E8: =(SUM(C19:I19)+Assumptions!$B$7+Assumptions!$B$9-Assumptions!$B$8)/Assumptions!$B$10 -> 0.54839952
B9: 1 | C9: =(SUM(C20:I20)+Assumptions!$B$7+Assumptions!$B$9-Assumptions!$B$8)/Assumptions!$B$10 -> 0.78243892 | D9: =(SUM(C21:I21)+Assumptions!$B$7+Assumptions!$B$9-Assumptions!$B$8)/Assumptions!$B$10 -> 0.76474871 | E9: =(SUM(C22:I22)+Assumptions!$B$7+Assumptions!$B$9-Assumptions!$B$8)/Assumptions!$B$10 -> 0.74838973
B10: 1.2 | C10: =(SUM(C23:I23)+Assumptions!$B$7+Assumptions!$B$9-Assumptions!$B$8)/Assumptions!$B$10 -> 1.0042958 | D10: =(SUM(C24:I24)+Assumptions!$B$7+Assumptions!$B$9-Assumptions!$B$8)/Assumptions!$B$10 -> 0.9752217 | E10: =(SUM(C25:I25)+Assumptions!$B$7+Assumptions!$B$9-Assumptions!$B$8)/Assumptions!$B$10 -> 0.94837994
A15: Auditable discounted-cash-flow helpers
A17: Driver 0.8× / rate column 1 | C17: =(((((Operating!$C$10*Operating!$C$11*Operating!$C$12*$B$8)*(1-Operating!$C$14)-Operating!$C$10*Operating!$C$13-Operating!$C$16)-MAX(0,((Operating!$C$10*Operating!$C$11*Operating!$C$12*$B$8)*(1-Operating!$C$14)-Operating!$C$10*Operating!$C$13-Operating!$C$16))*Operating!$C$15)+Operating!$C$16-Operating!$C$17-Operating!$C$18-Operating!$C$19)*Operating!$B$5-Operating!$C$20+IF(1=Operating!$B$7,Operating!$B$6,0))/(1+C7)^1 -> 22867286 | D17: =(((((Operating!$D$10*Operating!$D$11*Operating!$D$12*$B$8)*(1-Operating!$D$14)-Operating!$D$10*Operating!$D$13-Operating!$D$16)-MAX(0,((Operating!$D$10*Operating!$D$11*Operating!$D$12*$B$8)*(1-Operating!$D$14)-Operating!$D$10*Operating!$D$13-Operating!$D$16))*Operating!$D$15)+Operating!$D$16-Operating!$D$17-Operating!$D$18-Operating!$D$19)*Operating!$B$5-Operating!$D$20+IF(2=Operating!$B$7,Operating!$B$6,0))/(1+C7)^2 -> 37784728 | E17: =(((((Operating!$E$10*Operating!$E$11*Operating!$E$12*$B$8)*(1-Operating!$E$14)-Operating!$E$10*Operating!$E$13-Operating!$E$16)-MAX(0,((Operating!$E$10*Operating!$E$11*Operating!$E$12*$B$8)*(1-Operating!$E$14)-Operating!$E$10*Operating!$E$13-Operating!$E$16))*Operating!$E$15)+Operating!$E$16-Operating!$E$17-Operating!$E$18-Operating!$E$19)*Operating!$B$5-Operating!$E$20+IF(3=Operating!$B$7,Operating!$B$6,0))/(1+C7)^3 -> 34985859 | F17: =(((((Operating!$F$10*Operating!$F$11*Operating!$F$12*$B$8)*(1-Operating!$F$14)-Operating!$F$10*Operating!$F$13-Operating!$F$16)-MAX(0,((Operating!$F$10*Operating!$F$11*Operating!$F$12*$B$8)*(1-Operating!$F$14)-Operating!$F$10*Operating!$F$13-Operating!$F$16))*Operating!$F$15)+Operating!$F$16-Operating!$F$17-Operating!$F$18-Operating!$F$19)*Operating!$B$5-Operating!$F$20+IF(4=Operating!$B$7,Operating!$B$6,0))/(1+C7)^4 -> 32394314 | G17: =(((((Operating!$G$10*Operating!$G$11*Operating!$G$12*$B$8)*(1-Operating!$G$14)-Operating!$G$10*Operating!$G$13-Operating!$G$16)-MAX(0,((Operating!$G$10*Operating!$G$11*Operating!$G$12*$B$8)*(1-Operating!$G$14)-Operating!$G$10*Operating!$G$13-Operating!$G$16))*Operating!$G$15)+Operating!$G$16-Operating!$G$17-Operating!$G$18-Operating!$G$19)*Operating!$B$5-Operating!$G$20+IF(5=Operating!$B$7,Operating!$B$6,0))/(1+C7)^5 -> -4034424.7 | H17: =(((((Operating!$H$10*Operating!$H$11*Operating!$H$12*$B$8)*(1-Operating!$H$14)-Operating!$H$10*Operating!$H$13-Operating!$H$16)-MAX(0,((Operating!$H$10*Operating!$H$11*Operating!$H$12*$B$8)*(1-Operating!$H$14)-Operating!$H$10*Operating!$H$13-Operating!$H$16))*Operating!$H$15)+Operating!$H$16-Operating!$H$17-Operating!$H$18-Operating!$H$19)*Operating!$B$5-Operating!$H$20+IF(6=Operating!$B$7,Operating!$B$6,0))/(1+C7)^6 -> 0 | I17: =(((((Operating!$I$10*Operating!$I$11*Operating!$I$12*$B$8)*(1-Operating!$I$14)-Operating!$I$10*Operating!$I$13-Operating!$I$16)-MAX(0,((Operating!$I$10*Operating!$I$11*Operating!$I$12*$B$8)*(1-Operating!$I$14)-Operating!$I$10*Operating!$I$13-Operating!$I$16))*Operating!$I$15)+Operating!$I$16-Operating!$I$17-Operating!$I$18-Operating!$I$19)*Operating!$B$5-Operating!$I$20+IF(7=Operating!$B$7,Operating!$B$6,0))/(1+C7)^7 -> 0
A18: Driver 0.8× / rate column 2 | C18: =(((((Operating!$C$10*Operating!$C$11*Operating!$C$12*$B$8)*(1-Operating!$C$14)-Operating!$C$10*Operating!$C$13-Operating!$C$16)-MAX(0,((Operating!$C$10*Operating!$C$11*Operating!$C$12*$B$8)*(1-Operating!$C$14)-Operating!$C$10*Operating!$C$13-Operating!$C$16))*Operating!$C$15)+Operating!$C$16-Operating!$C$17-Operating!$C$18-Operating!$C$19)*Operating!$B$5-Operating!$C$20+IF(1=Operating!$B$7,Operating!$B$6,0))/(1+D7)^1 -> 22451517 | D18: =(((((Operating!$D$10*Operating!$D$11*Operating!$D$12*$B$8)*(1-Operating!$D$14)-Operating!$D$10*Operating!$D$13-Operating!$D$16)-MAX(0,((Operating!$D$10*Operating!$D$11*Operating!$D$12*$B$8)*(1-Operating!$D$14)-Operating!$D$10*Operating!$D$13-Operating!$D$16))*Operating!$D$15)+Operating!$D$16-Operating!$D$17-Operating!$D$18-Operating!$D$19)*Operating!$B$5-Operating!$D$20+IF(2=Operating!$B$7,Operating!$B$6,0))/(1+D7)^2 -> 36423229 | E18: =(((((Operating!$E$10*Operating!$E$11*Operating!$E$12*$B$8)*(1-Operating!$E$14)-Operating!$E$10*Operating!$E$13-Operating!$E$16)-MAX(0,((Operating!$E$10*Operating!$E$11*Operating!$E$12*$B$8)*(1-Operating!$E$14)-Operating!$E$10*Operating!$E$13-Operating!$E$16))*Operating!$E$15)+Operating!$E$16-Operating!$E$17-Operating!$E$18-Operating!$E$19)*Operating!$B$5-Operating!$E$20+IF(3=Operating!$B$7,Operating!$B$6,0))/(1+D7)^3 -> 33112026 | F18: =(((((Operating!$F$10*Operating!$F$11*Operating!$F$12*$B$8)*(1-Operating!$F$14)-Operating!$F$10*Operating!$F$13-Operating!$F$16)-MAX(0,((Operating!$F$10*Operating!$F$11*Operating!$F$12*$B$8)*(1-Operating!$F$14)-Operating!$F$10*Operating!$F$13-Operating!$F$16))*Operating!$F$15)+Operating!$F$16-Operating!$F$17-Operating!$F$18-Operating!$F$19)*Operating!$B$5-Operating!$F$20+IF(4=Operating!$B$7,Operating!$B$6,0))/(1+D7)^4 -> 30101842 | G18: =(((((Operating!$G$10*Operating!$G$11*Operating!$G$12*$B$8)*(1-Operating!$G$14)-Operating!$G$10*Operating!$G$13-Operating!$G$16)-MAX(0,((Operating!$G$10*Operating!$G$11*Operating!$G$12*$B$8)*(1-Operating!$G$14)-Operating!$G$10*Operating!$G$13-Operating!$G$16))*Operating!$G$15)+Operating!$G$16-Operating!$G$17-Operating!$G$18-Operating!$G$19)*Operating!$B$5-Operating!$G$20+IF(5=Operating!$B$7,Operating!$B$6,0))/(1+D7)^5 -> -3680755.5 | H18: =(((((Operating!$H$10*Operating!$H$11*Operating!$H$12*$B$8)*(1-Operating!$H$14)-Operating!$H$10*Operating!$H$13-Operating!$H$16)-MAX(0,((Operating!$H$10*Operating!$H$11*Operating!$H$12*$B$8)*(1-Operating!$H$14)-Operating!$H$10*Operating!$H$13-Operating!$H$16))*Operating!$H$15)+Operating!$H$16-Operating!$H$17-Operating!$H$18-Operating!$H$19)*Operating!$B$5-Operating!$H$20+IF(6=Operating!$B$7,Operating!$B$6,0))/(1+D7)^6 -> 0 | I18: =(((((Operating!$I$10*Operating!$I$11*Operating!$I$12*$B$8)*(1-Operating!$I$14)-Operating!$I$10*Operating!$I$13-Operating!$I$16)-MAX(0,((Operating!$I$10*Operating!$I$11*Operating!$I$12*$B$8)*(1-Operating!$I$14)-Operating!$I$10*Operating!$I$13-Operating!$I$16))*Operating!$I$15)+Operating!$I$16-Operating!$I$17-Operating!$I$18-Operating!$I$19)*Operating!$B$5-Operating!$I$20+IF(7=Operating!$B$7,Operating!$B$6,0))/(1+D7)^7 -> 0
A19: Driver 0.8× / rate column 3 | C19: =(((((Operating!$C$10*Operating!$C$11*Operating!$C$12*$B$8)*(1-Operating!$C$14)-Operating!$C$10*Operating!$C$13-Operating!$C$16)-MAX(0,((Operating!$C$10*Operating!$C$11*Operating!$C$12*$B$8)*(1-Operating!$C$14)-Operating!$C$10*Operating!$C$13-Operating!$C$16))*Operating!$C$15)+Operating!$C$16-Operating!$C$17-Operating!$C$18-Operating!$C$19)*Operating!$B$5-Operating!$C$20+IF(1=Operating!$B$7,Operating!$B$6,0))/(1+E7)^1 -> 22050597 | D19: =(((((Operating!$D$10*Operating!$D$11*Operating!$D$12*$B$8)*(1-Operating!$D$14)-Operating!$D$10*Operating!$D$13-Operating!$D$16)-MAX(0,((Operating!$D$10*Operating!$D$11*Operating!$D$12*$B$8)*(1-Operating!$D$14)-Operating!$D$10*Operating!$D$13-Operating!$D$16))*Operating!$D$15)+Operating!$D$16-Operating!$D$17-Operating!$D$18-Operating!$D$19)*Operating!$B$5-Operating!$D$20+IF(2=Operating!$B$7,Operating!$B$6,0))/(1+E7)^2 -> 35134013 | E19: =(((((Operating!$E$10*Operating!$E$11*Operating!$E$12*$B$8)*(1-Operating!$E$14)-Operating!$E$10*Operating!$E$13-Operating!$E$16)-MAX(0,((Operating!$E$10*Operating!$E$11*Operating!$E$12*$B$8)*(1-Operating!$E$14)-Operating!$E$10*Operating!$E$13-Operating!$E$16))*Operating!$E$15)+Operating!$E$16-Operating!$E$17-Operating!$E$18-Operating!$E$19)*Operating!$B$5-Operating!$E$20+IF(3=Operating!$B$7,Operating!$B$6,0))/(1+E7)^3 -> 31369655 | F19: =(((((Operating!$F$10*Operating!$F$11*Operating!$F$12*$B$8)*(1-Operating!$F$14)-Operating!$F$10*Operating!$F$13-Operating!$F$16)-MAX(0,((Operating!$F$10*Operating!$F$11*Operating!$F$12*$B$8)*(1-Operating!$F$14)-Operating!$F$10*Operating!$F$13-Operating!$F$16))*Operating!$F$15)+Operating!$F$16-Operating!$F$17-Operating!$F$18-Operating!$F$19)*Operating!$B$5-Operating!$F$20+IF(4=Operating!$B$7,Operating!$B$6,0))/(1+E7)^4 -> 28008620 | G19: =(((((Operating!$G$10*Operating!$G$11*Operating!$G$12*$B$8)*(1-Operating!$G$14)-Operating!$G$10*Operating!$G$13-Operating!$G$16)-MAX(0,((Operating!$G$10*Operating!$G$11*Operating!$G$12*$B$8)*(1-Operating!$G$14)-Operating!$G$10*Operating!$G$13-Operating!$G$16))*Operating!$G$15)+Operating!$G$16-Operating!$G$17-Operating!$G$18-Operating!$G$19)*Operating!$B$5-Operating!$G$20+IF(5=Operating!$B$7,Operating!$B$6,0))/(1+E7)^5 -> -3363646 | H19: =(((((Operating!$H$10*Operating!$H$11*Operating!$H$12*$B$8)*(1-Operating!$H$14)-Operating!$H$10*Operating!$H$13-Operating!$H$16)-MAX(0,((Operating!$H$10*Operating!$H$11*Operating!$H$12*$B$8)*(1-Operating!$H$14)-Operating!$H$10*Operating!$H$13-Operating!$H$16))*Operating!$H$15)+Operating!$H$16-Operating!$H$17-Operating!$H$18-Operating!$H$19)*Operating!$B$5-Operating!$H$20+IF(6=Operating!$B$7,Operating!$B$6,0))/(1+E7)^6 -> 0 | I19: =(((((Operating!$I$10*Operating!$I$11*Operating!$I$12*$B$8)*(1-Operating!$I$14)-Operating!$I$10*Operating!$I$13-Operating!$I$16)-MAX(0,((Operating!$I$10*Operating!$I$11*Operating!$I$12*$B$8)*(1-Operating!$I$14)-Operating!$I$10*Operating!$I$13-Operating!$I$16))*Operating!$I$15)+Operating!$I$16-Operating!$I$17-Operating!$I$18-Operating!$I$19)*Operating!$B$5-Operating!$I$20+IF(7=Operating!$B$7,Operating!$B$6,0))/(1+E7)^7 -> 0
A20: Driver 1.0× / rate column 1 | C20: =(((((Operating!$C$10*Operating!$C$11*Operating!$C$12*$B$9)*(1-Operating!$C$14)-Operating!$C$10*Operating!$C$13-Operating!$C$16)-MAX(0,((Operating!$C$10*Operating!$C$11*Operating!$C$12*$B$9)*(1-Operating!$C$14)-Operating!$C$10*Operating!$C$13-Operating!$C$16))*Operating!$C$15)+Operating!$C$16-Operating!$C$17-Operating!$C$18-Operating!$C$19)*Operating!$B$5-Operating!$C$20+IF(1=Operating!$B$7,Operating!$B$6,0))/(1+C7)^1 -> 65026803 | D20: =(((((Operating!$D$10*Operating!$D$11*Operating!$D$12*$B$9)*(1-Operating!$D$14)-Operating!$D$10*Operating!$D$13-Operating!$D$16)-MAX(0,((Operating!$D$10*Operating!$D$11*Operating!$D$12*$B$9)*(1-Operating!$D$14)-Operating!$D$10*Operating!$D$13-Operating!$D$16))*Operating!$D$15)+Operating!$D$16-Operating!$D$17-Operating!$D$18-Operating!$D$19)*Operating!$B$5-Operating!$D$20+IF(2=Operating!$B$7,Operating!$B$6,0))/(1+C7)^2 -> 80974147 | E20: =(((((Operating!$E$10*Operating!$E$11*Operating!$E$12*$B$9)*(1-Operating!$E$14)-Operating!$E$10*Operating!$E$13-Operating!$E$16)-MAX(0,((Operating!$E$10*Operating!$E$11*Operating!$E$12*$B$9)*(1-Operating!$E$14)-Operating!$E$10*Operating!$E$13-Operating!$E$16))*Operating!$E$15)+Operating!$E$16-Operating!$E$17-Operating!$E$18-Operating!$E$19)*Operating!$B$5-Operating!$E$20+IF(3=Operating!$B$7,Operating!$B$6,0))/(1+C7)^3 -> 74976062 | F20: =(((((Operating!$F$10*Operating!$F$11*Operating!$F$12*$B$9)*(1-Operating!$F$14)-Operating!$F$10*Operating!$F$13-Operating!$F$16)-MAX(0,((Operating!$F$10*Operating!$F$11*Operating!$F$12*$B$9)*(1-Operating!$F$14)-Operating!$F$10*Operating!$F$13-Operating!$F$16))*Operating!$F$15)+Operating!$F$16-Operating!$F$17-Operating!$F$18-Operating!$F$19)*Operating!$B$5-Operating!$F$20+IF(4=Operating!$B$7,Operating!$B$6,0))/(1+C7)^4 -> 69422280 | G20: =(((((Operating!$G$10*Operating!$G$11*Operating!$G$12*$B$9)*(1-Operating!$G$14)-Operating!$G$10*Operating!$G$13-Operating!$G$16)-MAX(0,((Operating!$G$10*Operating!$G$11*Operating!$G$12*$B$9)*(1-Operating!$G$14)-Operating!$G$10*Operating!$G$13-Operating!$G$16))*Operating!$G$15)+Operating!$G$16-Operating!$G$17-Operating!$G$18-Operating!$G$19)*Operating!$B$5-Operating!$G$20+IF(5=Operating!$B$7,Operating!$B$6,0))/(1+C7)^5 -> 30250729 | H20: =(((((Operating!$H$10*Operating!$H$11*Operating!$H$12*$B$9)*(1-Operating!$H$14)-Operating!$H$10*Operating!$H$13-Operating!$H$16)-MAX(0,((Operating!$H$10*Operating!$H$11*Operating!$H$12*$B$9)*(1-Operating!$H$14)-Operating!$H$10*Operating!$H$13-Operating!$H$16))*Operating!$H$15)+Operating!$H$16-Operating!$H$17-Operating!$H$18-Operating!$H$19)*Operating!$B$5-Operating!$H$20+IF(6=Operating!$B$7,Operating!$B$6,0))/(1+C7)^6 -> 0 | I20: =(((((Operating!$I$10*Operating!$I$11*Operating!$I$12*$B$9)*(1-Operating!$I$14)-Operating!$I$10*Operating!$I$13-Operating!$I$16)-MAX(0,((Operating!$I$10*Operating!$I$11*Operating!$I$12*$B$9)*(1-Operating!$I$14)-Operating!$I$10*Operating!$I$13-Operating!$I$16))*Operating!$I$15)+Operating!$I$16-Operating!$I$17-Operating!$I$18-Operating!$I$19)*Operating!$B$5-Operating!$I$20+IF(7=Operating!$B$7,Operating!$B$6,0))/(1+C7)^7 -> 0
A21: Driver 1.0× / rate column 2 | C21: =(((((Operating!$C$10*Operating!$C$11*Operating!$C$12*$B$9)*(1-Operating!$C$14)-Operating!$C$10*Operating!$C$13-Operating!$C$16)-MAX(0,((Operating!$C$10*Operating!$C$11*Operating!$C$12*$B$9)*(1-Operating!$C$14)-Operating!$C$10*Operating!$C$13-Operating!$C$16))*Operating!$C$15)+Operating!$C$16-Operating!$C$17-Operating!$C$18-Operating!$C$19)*Operating!$B$5-Operating!$C$20+IF(1=Operating!$B$7,Operating!$B$6,0))/(1+D7)^1 -> 63844498 | D21: =(((((Operating!$D$10*Operating!$D$11*Operating!$D$12*$B$9)*(1-Operating!$D$14)-Operating!$D$10*Operating!$D$13-Operating!$D$16)-MAX(0,((Operating!$D$10*Operating!$D$11*Operating!$D$12*$B$9)*(1-Operating!$D$14)-Operating!$D$10*Operating!$D$13-Operating!$D$16))*Operating!$D$15)+Operating!$D$16-Operating!$D$17-Operating!$D$18-Operating!$D$19)*Operating!$B$5-Operating!$D$20+IF(2=Operating!$B$7,Operating!$B$6,0))/(1+D7)^2 -> 78056401 | E21: =(((((Operating!$E$10*Operating!$E$11*Operating!$E$12*$B$9)*(1-Operating!$E$14)-Operating!$E$10*Operating!$E$13-Operating!$E$16)-MAX(0,((Operating!$E$10*Operating!$E$11*Operating!$E$12*$B$9)*(1-Operating!$E$14)-Operating!$E$10*Operating!$E$13-Operating!$E$16))*Operating!$E$15)+Operating!$E$16-Operating!$E$17-Operating!$E$18-Operating!$E$19)*Operating!$B$5-Operating!$E$20+IF(3=Operating!$B$7,Operating!$B$6,0))/(1+D7)^3 -> 70960364 | F21: =(((((Operating!$F$10*Operating!$F$11*Operating!$F$12*$B$9)*(1-Operating!$F$14)-Operating!$F$10*Operating!$F$13-Operating!$F$16)-MAX(0,((Operating!$F$10*Operating!$F$11*Operating!$F$12*$B$9)*(1-Operating!$F$14)-Operating!$F$10*Operating!$F$13-Operating!$F$16))*Operating!$F$15)+Operating!$F$16-Operating!$F$17-Operating!$F$18-Operating!$F$19)*Operating!$B$5-Operating!$F$20+IF(4=Operating!$B$7,Operating!$B$6,0))/(1+D7)^4 -> 64509422 | G21: =(((((Operating!$G$10*Operating!$G$11*Operating!$G$12*$B$9)*(1-Operating!$G$14)-Operating!$G$10*Operating!$G$13-Operating!$G$16)-MAX(0,((Operating!$G$10*Operating!$G$11*Operating!$G$12*$B$9)*(1-Operating!$G$14)-Operating!$G$10*Operating!$G$13-Operating!$G$16))*Operating!$G$15)+Operating!$G$16-Operating!$G$17-Operating!$G$18-Operating!$G$19)*Operating!$B$5-Operating!$G$20+IF(5=Operating!$B$7,Operating!$B$6,0))/(1+D7)^5 -> 27598863 | H21: =(((((Operating!$H$10*Operating!$H$11*Operating!$H$12*$B$9)*(1-Operating!$H$14)-Operating!$H$10*Operating!$H$13-Operating!$H$16)-MAX(0,((Operating!$H$10*Operating!$H$11*Operating!$H$12*$B$9)*(1-Operating!$H$14)-Operating!$H$10*Operating!$H$13-Operating!$H$16))*Operating!$H$15)+Operating!$H$16-Operating!$H$17-Operating!$H$18-Operating!$H$19)*Operating!$B$5-Operating!$H$20+IF(6=Operating!$B$7,Operating!$B$6,0))/(1+D7)^6 -> 0 | I21: =(((((Operating!$I$10*Operating!$I$11*Operating!$I$12*$B$9)*(1-Operating!$I$14)-Operating!$I$10*Operating!$I$13-Operating!$I$16)-MAX(0,((Operating!$I$10*Operating!$I$11*Operating!$I$12*$B$9)*(1-Operating!$I$14)-Operating!$I$10*Operating!$I$13-Operating!$I$16))*Operating!$I$15)+Operating!$I$16-Operating!$I$17-Operating!$I$18-Operating!$I$19)*Operating!$B$5-Operating!$I$20+IF(7=Operating!$B$7,Operating!$B$6,0))/(1+D7)^7 -> 0
A22: Driver 1.0× / rate column 3 | C22: =(((((Operating!$C$10*Operating!$C$11*Operating!$C$12*$B$9)*(1-Operating!$C$14)-Operating!$C$10*Operating!$C$13-Operating!$C$16)-MAX(0,((Operating!$C$10*Operating!$C$11*Operating!$C$12*$B$9)*(1-Operating!$C$14)-Operating!$C$10*Operating!$C$13-Operating!$C$16))*Operating!$C$15)+Operating!$C$16-Operating!$C$17-Operating!$C$18-Operating!$C$19)*Operating!$B$5-Operating!$C$20+IF(1=Operating!$B$7,Operating!$B$6,0))/(1+E7)^1 -> 62704417 | D22: =(((((Operating!$D$10*Operating!$D$11*Operating!$D$12*$B$9)*(1-Operating!$D$14)-Operating!$D$10*Operating!$D$13-Operating!$D$16)-MAX(0,((Operating!$D$10*Operating!$D$11*Operating!$D$12*$B$9)*(1-Operating!$D$14)-Operating!$D$10*Operating!$D$13-Operating!$D$16))*Operating!$D$15)+Operating!$D$16-Operating!$D$17-Operating!$D$18-Operating!$D$19)*Operating!$B$5-Operating!$D$20+IF(2=Operating!$B$7,Operating!$B$6,0))/(1+E7)^2 -> 75293563 | E22: =(((((Operating!$E$10*Operating!$E$11*Operating!$E$12*$B$9)*(1-Operating!$E$14)-Operating!$E$10*Operating!$E$13-Operating!$E$16)-MAX(0,((Operating!$E$10*Operating!$E$11*Operating!$E$12*$B$9)*(1-Operating!$E$14)-Operating!$E$10*Operating!$E$13-Operating!$E$16))*Operating!$E$15)+Operating!$E$16-Operating!$E$17-Operating!$E$18-Operating!$E$19)*Operating!$B$5-Operating!$E$20+IF(3=Operating!$B$7,Operating!$B$6,0))/(1+E7)^3 -> 67226395 | F22: =(((((Operating!$F$10*Operating!$F$11*Operating!$F$12*$B$9)*(1-Operating!$F$14)-Operating!$F$10*Operating!$F$13-Operating!$F$16)-MAX(0,((Operating!$F$10*Operating!$F$11*Operating!$F$12*$B$9)*(1-Operating!$F$14)-Operating!$F$10*Operating!$F$13-Operating!$F$16))*Operating!$F$15)+Operating!$F$16-Operating!$F$17-Operating!$F$18-Operating!$F$19)*Operating!$B$5-Operating!$F$20+IF(4=Operating!$B$7,Operating!$B$6,0))/(1+E7)^4 -> 60023567 | G22: =(((((Operating!$G$10*Operating!$G$11*Operating!$G$12*$B$9)*(1-Operating!$G$14)-Operating!$G$10*Operating!$G$13-Operating!$G$16)-MAX(0,((Operating!$G$10*Operating!$G$11*Operating!$G$12*$B$9)*(1-Operating!$G$14)-Operating!$G$10*Operating!$G$13-Operating!$G$16))*Operating!$G$15)+Operating!$G$16-Operating!$G$17-Operating!$G$18-Operating!$G$19)*Operating!$B$5-Operating!$G$20+IF(5=Operating!$B$7,Operating!$B$6,0))/(1+E7)^5 -> 25221128 | H22: =(((((Operating!$H$10*Operating!$H$11*Operating!$H$12*$B$9)*(1-Operating!$H$14)-Operating!$H$10*Operating!$H$13-Operating!$H$16)-MAX(0,((Operating!$H$10*Operating!$H$11*Operating!$H$12*$B$9)*(1-Operating!$H$14)-Operating!$H$10*Operating!$H$13-Operating!$H$16))*Operating!$H$15)+Operating!$H$16-Operating!$H$17-Operating!$H$18-Operating!$H$19)*Operating!$B$5-Operating!$H$20+IF(6=Operating!$B$7,Operating!$B$6,0))/(1+E7)^6 -> 0 | I22: =(((((Operating!$I$10*Operating!$I$11*Operating!$I$12*$B$9)*(1-Operating!$I$14)-Operating!$I$10*Operating!$I$13-Operating!$I$16)-MAX(0,((Operating!$I$10*Operating!$I$11*Operating!$I$12*$B$9)*(1-Operating!$I$14)-Operating!$I$10*Operating!$I$13-Operating!$I$16))*Operating!$I$15)+Operating!$I$16-Operating!$I$17-Operating!$I$18-Operating!$I$19)*Operating!$B$5-Operating!$I$20+IF(7=Operating!$B$7,Operating!$B$6,0))/(1+E7)^7 -> 0
A23: Driver 1.2× / rate column 1 | C23: =(((((Operating!$C$10*Operating!$C$11*Operating!$C$12*$B$10)*(1-Operating!$C$14)-Operating!$C$10*Operating!$C$13-Operating!$C$16)-MAX(0,((Operating!$C$10*Operating!$C$11*Operating!$C$12*$B$10)*(1-Operating!$C$14)-Operating!$C$10*Operating!$C$13-Operating!$C$16))*Operating!$C$15)+Operating!$C$16-Operating!$C$17-Operating!$C$18-Operating!$C$19)*Operating!$B$5-Operating!$C$20+IF(1=Operating!$B$7,Operating!$B$6,0))/(1+C7)^1 -> 1.0718632e+08 | D23: =(((((Operating!$D$10*Operating!$D$11*Operating!$D$12*$B$10)*(1-Operating!$D$14)-Operating!$D$10*Operating!$D$13-Operating!$D$16)-MAX(0,((Operating!$D$10*Operating!$D$11*Operating!$D$12*$B$10)*(1-Operating!$D$14)-Operating!$D$10*Operating!$D$13-Operating!$D$16))*Operating!$D$15)+Operating!$D$16-Operating!$D$17-Operating!$D$18-Operating!$D$19)*Operating!$B$5-Operating!$D$20+IF(2=Operating!$B$7,Operating!$B$6,0))/(1+C7)^2 -> 1.2416357e+08 | E23: =(((((Operating!$E$10*Operating!$E$11*Operating!$E$12*$B$10)*(1-Operating!$E$14)-Operating!$E$10*Operating!$E$13-Operating!$E$16)-MAX(0,((Operating!$E$10*Operating!$E$11*Operating!$E$12*$B$10)*(1-Operating!$E$14)-Operating!$E$10*Operating!$E$13-Operating!$E$16))*Operating!$E$15)+Operating!$E$16-Operating!$E$17-Operating!$E$18-Operating!$E$19)*Operating!$B$5-Operating!$E$20+IF(3=Operating!$B$7,Operating!$B$6,0))/(1+C7)^3 -> 1.1496626e+08 | F23: =(((((Operating!$F$10*Operating!$F$11*Operating!$F$12*$B$10)*(1-Operating!$F$14)-Operating!$F$10*Operating!$F$13-Operating!$F$16)-MAX(0,((Operating!$F$10*Operating!$F$11*Operating!$F$12*$B$10)*(1-Operating!$F$14)-Operating!$F$10*Operating!$F$13-Operating!$F$16))*Operating!$F$15)+Operating!$F$16-Operating!$F$17-Operating!$F$18-Operating!$F$19)*Operating!$B$5-Operating!$F$20+IF(4=Operating!$B$7,Operating!$B$6,0))/(1+C7)^4 -> 1.0645025e+08 | G23: =(((((Operating!$G$10*Operating!$G$11*Operating!$G$12*$B$10)*(1-Operating!$G$14)-Operating!$G$10*Operating!$G$13-Operating!$G$16)-MAX(0,((Operating!$G$10*Operating!$G$11*Operating!$G$12*$B$10)*(1-Operating!$G$14)-Operating!$G$10*Operating!$G$13-Operating!$G$16))*Operating!$G$15)+Operating!$G$16-Operating!$G$17-Operating!$G$18-Operating!$G$19)*Operating!$B$5-Operating!$G$20+IF(5=Operating!$B$7,Operating!$B$6,0))/(1+C7)^5 -> 64535882 | H23: =(((((Operating!$H$10*Operating!$H$11*Operating!$H$12*$B$10)*(1-Operating!$H$14)-Operating!$H$10*Operating!$H$13-Operating!$H$16)-MAX(0,((Operating!$H$10*Operating!$H$11*Operating!$H$12*$B$10)*(1-Operating!$H$14)-Operating!$H$10*Operating!$H$13-Operating!$H$16))*Operating!$H$15)+Operating!$H$16-Operating!$H$17-Operating!$H$18-Operating!$H$19)*Operating!$B$5-Operating!$H$20+IF(6=Operating!$B$7,Operating!$B$6,0))/(1+C7)^6 -> 0 | I23: =(((((Operating!$I$10*Operating!$I$11*Operating!$I$12*$B$10)*(1-Operating!$I$14)-Operating!$I$10*Operating!$I$13-Operating!$I$16)-MAX(0,((Operating!$I$10*Operating!$I$11*Operating!$I$12*$B$10)*(1-Operating!$I$14)-Operating!$I$10*Operating!$I$13-Operating!$I$16))*Operating!$I$15)+Operating!$I$16-Operating!$I$17-Operating!$I$18-Operating!$I$19)*Operating!$B$5-Operating!$I$20+IF(7=Operating!$B$7,Operating!$B$6,0))/(1+C7)^7 -> 0
A24: Driver 1.2× / rate column 2 | C24: =(((((Operating!$C$10*Operating!$C$11*Operating!$C$12*$B$10)*(1-Operating!$C$14)-Operating!$C$10*Operating!$C$13-Operating!$C$16)-MAX(0,((Operating!$C$10*Operating!$C$11*Operating!$C$12*$B$10)*(1-Operating!$C$14)-Operating!$C$10*Operating!$C$13-Operating!$C$16))*Operating!$C$15)+Operating!$C$16-Operating!$C$17-Operating!$C$18-Operating!$C$19)*Operating!$B$5-Operating!$C$20+IF(1=Operating!$B$7,Operating!$B$6,0))/(1+D7)^1 -> 1.0523748e+08 | D24: =(((((Operating!$D$10*Operating!$D$11*Operating!$D$12*$B$10)*(1-Operating!$D$14)-Operating!$D$10*Operating!$D$13-Operating!$D$16)-MAX(0,((Operating!$D$10*Operating!$D$11*Operating!$D$12*$B$10)*(1-Operating!$D$14)-Operating!$D$10*Operating!$D$13-Operating!$D$16))*Operating!$D$15)+Operating!$D$16-Operating!$D$17-Operating!$D$18-Operating!$D$19)*Operating!$B$5-Operating!$D$20+IF(2=Operating!$B$7,Operating!$B$6,0))/(1+D7)^2 -> 1.1968957e+08 | E24: =(((((Operating!$E$10*Operating!$E$11*Operating!$E$12*$B$10)*(1-Operating!$E$14)-Operating!$E$10*Operating!$E$13-Operating!$E$16)-MAX(0,((Operating!$E$10*Operating!$E$11*Operating!$E$12*$B$10)*(1-Operating!$E$14)-Operating!$E$10*Operating!$E$13-Operating!$E$16))*Operating!$E$15)+Operating!$E$16-Operating!$E$17-Operating!$E$18-Operating!$E$19)*Operating!$B$5-Operating!$E$20+IF(3=Operating!$B$7,Operating!$B$6,0))/(1+D7)^3 -> 1.088087e+08 | F24: =(((((Operating!$F$10*Operating!$F$11*Operating!$F$12*$B$10)*(1-Operating!$F$14)-Operating!$F$10*Operating!$F$13-Operating!$F$16)-MAX(0,((Operating!$F$10*Operating!$F$11*Operating!$F$12*$B$10)*(1-Operating!$F$14)-Operating!$F$10*Operating!$F$13-Operating!$F$16))*Operating!$F$15)+Operating!$F$16-Operating!$F$17-Operating!$F$18-Operating!$F$19)*Operating!$B$5-Operating!$F$20+IF(4=Operating!$B$7,Operating!$B$6,0))/(1+D7)^4 -> 98917002 | G24: =(((((Operating!$G$10*Operating!$G$11*Operating!$G$12*$B$10)*(1-Operating!$G$14)-Operating!$G$10*Operating!$G$13-Operating!$G$16)-MAX(0,((Operating!$G$10*Operating!$G$11*Operating!$G$12*$B$10)*(1-Operating!$G$14)-Operating!$G$10*Operating!$G$13-Operating!$G$16))*Operating!$G$15)+Operating!$G$16-Operating!$G$17-Operating!$G$18-Operating!$G$19)*Operating!$B$5-Operating!$G$20+IF(5=Operating!$B$7,Operating!$B$6,0))/(1+D7)^5 -> 58878482 | H24: =(((((Operating!$H$10*Operating!$H$11*Operating!$H$12*$B$10)*(1-Operating!$H$14)-Operating!$H$10*Operating!$H$13-Operating!$H$16)-MAX(0,((Operating!$H$10*Operating!$H$11*Operating!$H$12*$B$10)*(1-Operating!$H$14)-Operating!$H$10*Operating!$H$13-Operating!$H$16))*Operating!$H$15)+Operating!$H$16-Operating!$H$17-Operating!$H$18-Operating!$H$19)*Operating!$B$5-Operating!$H$20+IF(6=Operating!$B$7,Operating!$B$6,0))/(1+D7)^6 -> 0 | I24: =(((((Operating!$I$10*Operating!$I$11*Operating!$I$12*$B$10)*(1-Operating!$I$14)-Operating!$I$10*Operating!$I$13-Operating!$I$16)-MAX(0,((Operating!$I$10*Operating!$I$11*Operating!$I$12*$B$10)*(1-Operating!$I$14)-Operating!$I$10*Operating!$I$13-Operating!$I$16))*Operating!$I$15)+Operating!$I$16-Operating!$I$17-Operating!$I$18-Operating!$I$19)*Operating!$B$5-Operating!$I$20+IF(7=Operating!$B$7,Operating!$B$6,0))/(1+D7)^7 -> 0
